Workbook

Sheet PDF_page
A1: UAX Daily Snapshot for | C1: =TODAY()-1 -> 45644
A3: Reliability Snapshot
A4: Metric | B4: =TODAY()-1 -> 45644 | C4: MTD | D4: Goal | E4: DL Difference | F4: AA Difference | G4: Rank
A5: Completion | B5: 0.9979 | C5: 0.9879 | D5: 0.99 | E5: -1.13 | F5: -1.13 | G5: 3
A6: A:00 | B6: 0.722 | C6: 0.722 | D6: 0.9 | E6: -1.13 | F6: -0.24 | G6: 1
A7: D:00 | B7: 0.81 | C7: 0.722 | D7: 0.8 | E7: -6.4 | F7: 4.4 | G7: 2
A8: CS D:00 | B8: 0.81 | C8: 0.722 | D8: 0.8
A9: STAR D:00 | B9: 0.844 | C9: 0.844 | D9: 0.9
A10: Controllable Completion | B10: 0.9904 | C10: 0.9904 | D10: 0.99
A15: Cancel Detail
A16: Express Partner | B16: Scheduled | C16: Weather & | D16: Technical | E16: Flight | F16: Inflight | G16: Airport | H16: Network | I16: IT | J16: Catering Operations | K16: Total Cancels | L16: ES covered for this partner | M16: Total | N16: ES covered by this partner
B17: Departures | C17: ATC | D17: Operations | E17: Operations | F17: Services | G17: Operations | H17: Operations
A18: EV - ExpressJet | B18: 426 | E18: 19 | K18: 19 | L18: OO 2, AX 1 | M18: 3 | N18: 4
A19: OO - SkyWest | B19: 923 | C19: 7 | D19: 3 | E19: 1 | K19: 11 | L19: ZW 2 | M19: 2
A20: AX - Trans States | B20: 205 | K20: -
A21: YX - Republic | B21: 315 | C21: 5 | E21: 1 | H21: 3 | K21: 9 | L21: ZW 1 | M21: 1
A22: G7 - Go Jet | B22: 90 | K22: - | L22: OO 2, AX 5
A23: C5 - CommutAir | B23: 171 | K23: -
A24: YV - Mesa | B24: 383 | D24: 4 | K24: 4
A25: ZW - Air Wisconsin | B25: 292 | H25: 4 | K25: 4 | L25: OO 2, C5 1 | M25: 3 | N25: 2
A26: Total: | B26: 2805 | C26: =SUM(C18:C25) -> 12 | D26: 7 | E26: 21 | H26: 7 | K26: =SUM(K18:K25) -> 47 | M26: =SUM(M18:M25) -> 9 | N26: =SUM(N18:N25) -> 6
A30: Residual Cancel Detail
A31: Express Partner | B31: Scheduled | C31: Weather & | D31: Technical | E31: Flight | F31: Inflight | G31: Airport | H31: Network | I31: IT | J31: Catering Operations | K31: Total Cancels | L31: ES covered for this partner | M31: Total | N31: ES covered by this partner
B32: Departures | C32: ATC | D32: Operations | E32: Operations | F32: Services | G32: Operations | H32: Operations
A33: EV - ExpressJet | B33: 426 | E33: 2 | K33: 2
A34: OO - SkyWest | B34: 923 | C34: 1 | E34: 1 | K34: 2 | N34: 3
A35: AX - Trans States | B35: 205 | K35: -
A36: YX - Republic | B36: 315 | F36: 1 | K36: 1
A37: G7 - Go Jet | B37: 90 | K37: - | L37: OO 2, AX 5 | M37: 7
A38: C5 - CommutAir | B38: 171 | K38: -
A39: YV - Mesa | B39: 383 | D39: 3 | K39: 3
A40: ZW - Air Wisconsin | B40: 292 | K40: - | L40: OO 2, AX 1 | M40: 3 | N40: 2
A41: Total: | B41: 2805 | C41: 1 | D41: 3 | E41: 3 | K41: =SUM(K33:K40) -> 8 | M41: =SUM(M33:M40) -> 10 | N41: =SUM(N33:N40) -> 5

Sheet HTML_NAME
A1: HTML_PAGES
A2: PAGE_1

Sheet PAGE_1 (2)
B2: UAX Daily Snapshot for | D2: =TODAY()-1 -> 45644
B4: Reliability Snapshot | J4: Reliability Snapshot - Hubs
B5: Metric | C5: =TODAY()-1 -> 45644 | D5: MTD | E5: Goal | F5: DL Diff. | G5: AA Diff. | H5: Rank | I5: =MONTH(TODAY()-1) -> 12 | J5: Hub | K5: D:00 | L5: CS D:00 | M5: DL Diff. | N5: AA Diff. | O5: Rank | P5: Completion | Q5: DL Diff. | R5: AA Diff. | S5: Rank
B6: Completion | C6: =UA_SQL_1!N2/UA_SQL_1!M2 -> 852.5 | D6: =UA_SQL_1!F2/UA_SQL_1!E2 -> 0.0040492958 | E6: =SUMIF(EX_Goals!$B:$B,'PAGE_1 (2)'!$I$5,EX_Goals!$E:$E) -> 0.9701 | F6: =((UA_SQL_1!$N$2/UA_SQL_1!$M$2)-(SUMIF(OA_SQL_1!$A$1:$A$3,"DL",OA_SQL_1!$K$1:$K$3)/SUMIF(OA_SQL_1!$A$1:$A$3,"DL",OA_SQL_1!$I$1:$I$3)))*100 -> 85218.586 | G6: =((UA_SQL_1!$N$2/UA_SQL_1!$M$2)-(SUMIF(OA_SQL_1!$A$1:$A$3,"AA",OA_SQL_1!$K$1:$K$3)/SUMIF(OA_SQL_1!$A$1:$A$3,"AA",OA_SQL_1!$I$1:$I$3)))*100 -> 85221.573 | H6: =RANK!F2 -> 3 | J6: DEN
B7: A:00 | C7: =UA_SQL_1!Q2/UA_SQL_1!M2 -> 665.5 | D7: =UA_SQL_1!I2/UA_SQL_1!E2 -> 0.6415493 | E7: =SUMIF(EX_Goals!$B:$B,'PAGE_1 (2)'!$I$5,EX_Goals!$D:$D) -> 0.5766 | F7: =((UA_SQL_1!$Q$2/UA_SQL_1!$M$2)-(SUMIF(OA_SQL_1!$A$1:$A$3,"DL",OA_SQL_1!$L$1:$L$3)/SUMIF(OA_SQL_1!$A$1:$A$3,"DL",OA_SQL_1!$I$1:$I$3)))*100 -> 66504.526 | G7: =((UA_SQL_1!$Q$2/UA_SQL_1!$M$2)-(SUMIF(OA_SQL_1!$A$1:$A$3,"AA",OA_SQL_1!$L$1:$L$3)/SUMIF(OA_SQL_1!$A$1:$A$3,"AA",OA_SQL_1!$I$1:$I$3)))*100 -> 66511.17 | H7: =RANK!F3 -> 1 | J7: EWR
B8: CS D:00 | C8: =UA_SQL_1!P2/UA_SQL_1!M2 -> 648.5 | D8: =UA_SQL_1!H2/UA_SQL_1!E2 -> 0.71795775 | E8: =SUMIF(EX_Goals!$B:$B,'PAGE_1 (2)'!$I$5,EX_Goals!$C:$C) -> 0.6422 | F8: =((UA_SQL_1!$P$2/UA_SQL_1!$M$2)-(SUMIF(OA_SQL_1!$A$1:$A$3,"DL",OA_SQL_1!$J$1:$J$3)/SUMIF(OA_SQL_1!$A$1:$A$3,"DL",OA_SQL_1!$I$1:$I$3)))*100 -> 64804.124 | G8: =((UA_SQL_1!$P$2/UA_SQL_1!$M$2)-(SUMIF(OA_SQL_1!$A$1:$A$3,"AA",OA_SQL_1!$J$1:$J$3)/SUMIF(OA_SQL_1!$A$1:$A$3,"AA",OA_SQL_1!$I$1:$I$3)))*100 -> 64811.156 | H8: =RANK!F4 -> 1 | J8: IAD
B9: D:00 | C9: =UA_SQL_1!O2/UA_SQL_1!M2 -> 5.5 | D9: =UA_SQL_1!G2/UA_SQL_1!E2 -> 0.6943662 | E9: =SUMIF(EX_Goals!$B:$B,'PAGE_1 (2)'!$I$5,EX_Goals!$C:$C) -> 0.6422 | J9: IAH
B10: STAR D:00 | C10: =UA_SQL_1!S2/UA_SQL_1!R2 -> 1.1911403 | D10: =UA_SQL_1!K2/UA_SQL_1!J2 -> 0.19176262 | E10: =SUMIF(EX_Goals!$B:$B,'PAGE_1 (2)'!$I$5,EX_Goals!$F:$F) -> 0.77361606 | J10: LAX
B11: Controllable Completion | C11: =(UA_SQL_1!M2-UA_SQL_1!T2)/UA_SQL_1!M2 -> -135.5 | D11: =(UA_SQL_1!E2-UA_SQL_1!L2)/UA_SQL_1!E2 -> 0.87552817 | E11: =SUMIF(EX_Goals!$B:$B,'PAGE_1 (2)'!$I$5,EX_Goals!$G:$G) -> 0.99734316 | J11: ORD
B12: Total diverts | C12: =SUMIFS(TOTAL_DIVERTS_SQL_5!$B:$B,TOTAL_DIVERTS_SQL_5!A:A,"YEST") -> 3 | D12: =SUMIFS(TOTAL_DIVERTS_SQL_5!$B:$B,TOTAL_DIVERTS_SQL_5!A:A,"MTD") -> 9 | J12: SFO
B13: Diverts recovered | C13: =SUMIF(DIVERTS_RECOVERED_SQL_6!$A:$A,"YEST",DIVERTS_RECOVERED_SQL_6!$C:$C) -> 1 | D13: =SUMIF(DIVERTS_RECOVERED_SQL_6!$A:$A,"MTD",DIVERTS_RECOVERED_SQL_6!$C:$C) -> 6 | J13: Line
B19: Cancel Detail
B20: Express Partner | C20: Scheduled Departures | D20: Weather & ATC | E20: Technical Operations | F20: Flight Operations | G20: Inflight Services | H20: Airport Operations | I20: Network Operations | J20: IT | K20: Catering Operations | L20: Other | M20: Total Cancels | N20: ES covered for this partner | O20: Net Cancel | P20: ES covered by this partner
B21: EV - ExpressJet | C21: =SUMIF(SCH_DEP_SQL_4!$A:$A,'PAGE_1 (2)'!R21,SCH_DEP_SQL_4!$E:$E) -> 0 | D21: =IF(SUMIFS(CNXL_SQL_2!$F:$F,CNXL_SQL_2!$A:$A,'PAGE_1 (2)'!$R21,CNXL_SQL_2!$D:$D,'PAGE_1 (2)'!$S$21)=0,"",SUMIFS(CNXL_SQL_2!$F:$F,CNXL_SQL_2!$A:$A,'PAGE_1 (2)'!$R21,CNXL_SQL_2!$D:$D,'PAGE_1 (2)'!$S$21)) | E21: =IF(SUMIFS(CNXL_SQL_2!$F:$F,CNXL_SQL_2!$A:$A,'PAGE_1 (2)'!$R21,CNXL_SQL_2!$D:$D,'PAGE_1 (2)'!$S$22)=0,"",SUMIFS(CNXL_SQL_2!$F:$F,CNXL_SQL_2!$A:$A,'PAGE_1 (2)'!$R21,CNXL_SQL_2!$D:$D,'PAGE_1 (2)'!$S$22)) | F21: =IF(SUMIFS(CNXL_SQL_2!$F:$F,CNXL_SQL_2!$A:$A,'PAGE_1 (2)'!$R21,CNXL_SQL_2!$D:$D,'PAGE_1 (2)'!$S$23)=0,"",SUMIFS(CNXL_SQL_2!$F:$F,CNXL_SQL_2!$A:$A,'PAGE_1 (2)'!$R21,CNXL_SQL_2!$D:$D,'PAGE_1 (2)'!$S$23)) | G21: =IF(SUMIFS(CNXL_SQL_2!$F:$F,CNXL_SQL_2!$A:$A,'PAGE_1 (2)'!$R21,CNXL_SQL_2!$D:$D,'PAGE_1 (2)'!$S$24)=0,"",SUMIFS(CNXL_SQL_2!$F:$F,CNXL_SQL_2!$A:$A,'PAGE_1 (2)'!$R21,CNXL_SQL_2!$D:$D,'PAGE_1 (2)'!$S$24)) | H21: =IF(SUMIFS(CNXL_SQL_2!$F:$F,CNXL_SQL_2!$A:$A,'PAGE_1 (2)'!$R21,CNXL_SQL_2!$D:$D,'PAGE_1 (2)'!$S$25)=0,"",SUMIFS(CNXL_SQL_2!$F:$F,CNXL_SQL_2!$A:$A,'PAGE_1 (2)'!$R21,CNXL_SQL_2!$D:$D,'PAGE_1 (2)'!$S$25)) | I21: =IF(SUMIFS(CNXL_SQL_2!$F:$F,CNXL_SQL_2!$A:$A,'PAGE_1 (2)'!$R21,CNXL_SQL_2!$D:$D,'PAGE_1 (2)'!$S$26)=0,"",SUMIFS(CNXL_SQL_2!$F:$F,CNXL_SQL_2!$A:$A,'PAGE_1 (2)'!$R21,CNXL_SQL_2!$D:$D,'PAGE_1 (2)'!$S$26)) | J21: =IF(SUMIFS(CNXL_SQL_2!$F:$F,CNXL_SQL_2!$A:$A,'PAGE_1 (2)'!$R21,CNXL_SQL_2!$D:$D,'PAGE_1 (2)'!$S$27)=0,"",SUMIFS(CNXL_SQL_2!$F:$F,CNXL_SQL_2!$A:$A,'PAGE_1 (2)'!$R21,CNXL_SQL_2!$D:$D,'PAGE_1 (2)'!$S$27)) | K21: =IF(SUMIFS(CNXL_SQL_2!$F:$F,CNXL_SQL_2!$A:$A,'PAGE_1 (2)'!$R21,CNXL_SQL_2!$D:$D,'PAGE_1 (2)'!$S$28)=0,"",SUMIFS(CNXL_SQL_2!$F:$F,CNXL_SQL_2!$A:$A,'PAGE_1 (2)'!$R21,CNXL_SQL_2!$D:$D,'PAGE_1 (2)'!$S$28)) | L21: =IF(SUMIFS(CNXL_SQL_2!$F:$F,CNXL_SQL_2!$A:$A,'PAGE_1 (2)'!$R21,CNXL_SQL_2!$D:$D,'PAGE_1 (2)'!$S$29)=0,"",SUMIFS(CNXL_SQL_2!$F:$F,CNXL_SQL_2!$A:$A,'PAGE_1 (2)'!$R21,CNXL_SQL_2!$D:$D,'PAGE_1 (2)'!$S$29)) | M21: =IF(SUM(D21:L21)=0,"",SUM(D21:L21)) | N21: =ES_MATRIX!K3 | O21: =IFERROR(M21-ES_MATRIX!L3,"") | P21: =IF(SUMIF(CNXL_SQL_2!$E:$E,'PAGE_1 (2)'!R21,CNXL_SQL_2!$F:$F)=0,"",SUMIF(CNXL_SQL_2!$E:$E,'PAGE_1 (2)'!R21,CNXL_SQL_2!$F:$F)) | R21: EV | S21: WEATHER/ATC
B22: OO - SkyWest | C22: =SUMIF(SCH_DEP_SQL_4!$A:$A,'PAGE_1 (2)'!R22,SCH_DEP_SQL_4!$E:$E) -> 816 | D22: =IF(SUMIFS(CNXL_SQL_2!$F:$F,CNXL_SQL_2!$A:$A,'PAGE_1 (2)'!$R22,CNXL_SQL_2!$D:$D,'PAGE_1 (2)'!$S$21)=0,"",SUMIFS(CNXL_SQL_2!$F:$F,CNXL_SQL_2!$A:$A,'PAGE_1 (2)'!$R22,CNXL_SQL_2!$D:$D,'PAGE_1 (2)'!$S$21)) -> 10 | E22: =IF(SUMIFS(CNXL_SQL_2!$F:$F,CNXL_SQL_2!$A:$A,'PAGE_1 (2)'!$R22,CNXL_SQL_2!$D:$D,'PAGE_1 (2)'!$S$22)=0,"",SUMIFS(CNXL_SQL_2!$F:$F,CNXL_SQL_2!$A:$A,'PAGE_1 (2)'!$R22,CNXL_SQL_2!$D:$D,'PAGE_1 (2)'!$S$22)) | F22: =IF(SUMIFS(CNXL_SQL_2!$F:$F,CNXL_SQL_2!$A:$A,'PAGE_1 (2)'!$R22,CNXL_SQL_2!$D:$D,'PAGE_1 (2)'!$S$23)=0,"",SUMIFS(CNXL_SQL_2!$F:$F,CNXL_SQL_2!$A:$A,'PAGE_1 (2)'!$R22,CNXL_SQL_2!$D:$D,'PAGE_1 (2)'!$S$23)) | G22: =IF(SUMIFS(CNXL_SQL_2!$F:$F,CNXL_SQL_2!$A:$A,'PAGE_1 (2)'!$R22,CNXL_SQL_2!$D:$D,'PAGE_1 (2)'!$S$24)=0,"",SUMIFS(CNXL_SQL_2!$F:$F,CNXL_SQL_2!$A:$A,'PAGE_1 (2)'!$R22,CNXL_SQL_2!$D:$D,'PAGE_1 (2)'!$S$24)) | H22: =IF(SUMIFS(CNXL_SQL_2!$F:$F,CNXL_SQL_2!$A:$A,'PAGE_1 (2)'!$R22,CNXL_SQL_2!$D:$D,'PAGE_1 (2)'!$S$25)=0,"",SUMIFS(CNXL_SQL_2!$F:$F,CNXL_SQL_2!$A:$A,'PAGE_1 (2)'!$R22,CNXL_SQL_2!$D:$D,'PAGE_1 (2)'!$S$25)) | I22: =IF(SUMIFS(CNXL_SQL_2!$F:$F,CNXL_SQL_2!$A:$A,'PAGE_1 (2)'!$R22,CNXL_SQL_2!$D:$D,'PAGE_1 (2)'!$S$26)=0,"",SUMIFS(CNXL_SQL_2!$F:$F,CNXL_SQL_2!$A:$A,'PAGE_1 (2)'!$R22,CNXL_SQL_2!$D:$D,'PAGE_1 (2)'!$S$26)) | J22: =IF(SUMIFS(CNXL_SQL_2!$F:$F,CNXL_SQL_2!$A:$A,'PAGE_1 (2)'!$R22,CNXL_SQL_2!$D:$D,'PAGE_1 (2)'!$S$27)=0,"",SUMIFS(CNXL_SQL_2!$F:$F,CNXL_SQL_2!$A:$A,'PAGE_1 (2)'!$R22,CNXL_SQL_2!$D:$D,'PAGE_1 (2)'!$S$27)) | K22: =IF(SUMIFS(CNXL_SQL_2!$F:$F,CNXL_SQL_2!$A:$A,'PAGE_1 (2)'!$R22,CNXL_SQL_2!$D:$D,'PAGE_1 (2)'!$S$28)=0,"",SUMIFS(CNXL_SQL_2!$F:$F,CNXL_SQL_2!$A:$A,'PAGE_1 (2)'!$R22,CNXL_SQL_2!$D:$D,'PAGE_1 (2)'!$S$28)) | L22: =IF(SUMIFS(CNXL_SQL_2!$F:$F,CNXL_SQL_2!$A:$A,'PAGE_1 (2)'!$R22,CNXL_SQL_2!$D:$D,'PAGE_1 (2)'!$S$29)=0,"",SUMIFS(CNXL_SQL_2!$F:$F,CNXL_SQL_2!$A:$A,'PAGE_1 (2)'!$R22,CNXL_SQL_2!$D:$D,'PAGE_1 (2)'!$S$29)) | M22: =IF(SUM(D22:L22)=0,"",SUM(D22:L22)) -> 10 | N22: =ES_MATRIX!K4 | O22: =IFERROR(M22-ES_MATRIX!L4,"") -> 10 | P22: =IF(SUMIF(CNXL_SQL_2!$E:$E,'PAGE_1 (2)'!R22,CNXL_SQL_2!$F:$F)=0,"",SUMIF(CNXL_SQL_2!$E:$E,'PAGE_1 (2)'!R22,CNXL_SQL_2!$F:$F)) | R22: OO | S22: TECHNICAL OPERATIONS-AIRCRAFT
B23: AX - Trans States | C23: =SUMIF(SCH_DEP_SQL_4!$A:$A,'PAGE_1 (2)'!R23,SCH_DEP_SQL_4!$E:$E) -> 0 | D23: =IF(SUMIFS(CNXL_SQL_2!$F:$F,CNXL_SQL_2!$A:$A,'PAGE_1 (2)'!$R23,CNXL_SQL_2!$D:$D,'PAGE_1 (2)'!$S$21)=0,"",SUMIFS(CNXL_SQL_2!$F:$F,CNXL_SQL_2!$A:$A,'PAGE_1 (2)'!$R23,CNXL_SQL_2!$D:$D,'PAGE_1 (2)'!$S$21)) | E23: =IF(SUMIFS(CNXL_SQL_2!$F:$F,CNXL_SQL_2!$A:$A,'PAGE_1 (2)'!$R23,CNXL_SQL_2!$D:$D,'PAGE_1 (2)'!$S$22)=0,"",SUMIFS(CNXL_SQL_2!$F:$F,CNXL_SQL_2!$A:$A,'PAGE_1 (2)'!$R23,CNXL_SQL_2!$D:$D,'PAGE_1 (2)'!$S$22)) | F23: =IF(SUMIFS(CNXL_SQL_2!$F:$F,CNXL_SQL_2!$A:$A,'PAGE_1 (2)'!$R23,CNXL_SQL_2!$D:$D,'PAGE_1 (2)'!$S$23)=0,"",SUMIFS(CNXL_SQL_2!$F:$F,CNXL_SQL_2!$A:$A,'PAGE_1 (2)'!$R23,CNXL_SQL_2!$D:$D,'PAGE_1 (2)'!$S$23)) | G23: =IF(SUMIFS(CNXL_SQL_2!$F:$F,CNXL_SQL_2!$A:$A,'PAGE_1 (2)'!$R23,CNXL_SQL_2!$D:$D,'PAGE_1 (2)'!$S$24)=0,"",SUMIFS(CNXL_SQL_2!$F:$F,CNXL_SQL_2!$A:$A,'PAGE_1 (2)'!$R23,CNXL_SQL_2!$D:$D,'PAGE_1 (2)'!$S$24)) | H23: =IF(SUMIFS(CNXL_SQL_2!$F:$F,CNXL_SQL_2!$A:$A,'PAGE_1 (2)'!$R23,CNXL_SQL_2!$D:$D,'PAGE_1 (2)'!$S$25)=0,"",SUMIFS(CNXL_SQL_2!$F:$F,CNXL_SQL_2!$A:$A,'PAGE_1 (2)'!$R23,CNXL_SQL_2!$D:$D,'PAGE_1 (2)'!$S$25)) | I23: =IF(SUMIFS(CNXL_SQL_2!$F:$F,CNXL_SQL_2!$A:$A,'PAGE_1 (2)'!$R23,CNXL_SQL_2!$D:$D,'PAGE_1 (2)'!$S$26)=0,"",SUMIFS(CNXL_SQL_2!$F:$F,CNXL_SQL_2!$A:$A,'PAGE_1 (2)'!$R23,CNXL_SQL_2!$D:$D,'PAGE_1 (2)'!$S$26)) | J23: =IF(SUMIFS(CNXL_SQL_2!$F:$F,CNXL_SQL_2!$A:$A,'PAGE_1 (2)'!$R23,CNXL_SQL_2!$D:$D,'PAGE_1 (2)'!$S$27)=0,"",SUMIFS(CNXL_SQL_2!$F:$F,CNXL_SQL_2!$A:$A,'PAGE_1 (2)'!$R23,CNXL_SQL_2!$D:$D,'PAGE_1 (2)'!$S$27)) | K23: =IF(SUMIFS(CNXL_SQL_2!$F:$F,CNXL_SQL_2!$A:$A,'PAGE_1 (2)'!$R23,CNXL_SQL_2!$D:$D,'PAGE_1 (2)'!$S$28)=0,"",SUMIFS(CNXL_SQL_2!$F:$F,CNXL_SQL_2!$A:$A,'PAGE_1 (2)'!$R23,CNXL_SQL_2!$D:$D,'PAGE_1 (2)'!$S$28)) | L23: =IF(SUMIFS(CNXL_SQL_2!$F:$F,CNXL_SQL_2!$A:$A,'PAGE_1 (2)'!$R23,CNXL_SQL_2!$D:$D,'PAGE_1 (2)'!$S$29)=0,"",SUMIFS(CNXL_SQL_2!$F:$F,CNXL_SQL_2!$A:$A,'PAGE_1 (2)'!$R23,CNXL_SQL_2!$D:$D,'PAGE_1 (2)'!$S$29)) | M23: =IF(SUM(D23:L23)=0,"",SUM(D23:L23)) | N23: =ES_MATRIX!K5 | O23: =IFERROR(M23-ES_MATRIX!L5,"") | P23: =IF(SUMIF(CNXL_SQL_2!$E:$E,'PAGE_1 (2)'!R23,CNXL_SQL_2!$F:$F)=0,"",SUMIF(CNXL_SQL_2!$E:$E,'PAGE_1 (2)'!R23,CNXL_SQL_2!$F:$F)) | R23: AX | S23: FLIGHT OPERATIONS
B24: YX - Republic | C24: =SUMIF(SCH_DEP_SQL_4!$A:$A,'PAGE_1 (2)'!R24,SCH_DEP_SQL_4!$E:$E) -> 297 | D24: =IF(SUMIFS(CNXL_SQL_2!$F:$F,CNXL_SQL_2!$A:$A,'PAGE_1 (2)'!$R24,CNXL_SQL_2!$D:$D,'PAGE_1 (2)'!$S$21)=0,"",SUMIFS(CNXL_SQL_2!$F:$F,CNXL_SQL_2!$A:$A,'PAGE_1 (2)'!$R24,CNXL_SQL_2!$D:$D,'PAGE_1 (2)'!$S$21)) | E24: =IF(SUMIFS(CNXL_SQL_2!$F:$F,CNXL_SQL_2!$A:$A,'PAGE_1 (2)'!$R24,CNXL_SQL_2!$D:$D,'PAGE_1 (2)'!$S$22)=0,"",SUMIFS(CNXL_SQL_2!$F:$F,CNXL_SQL_2!$A:$A,'PAGE_1 (2)'!$R24,CNXL_SQL_2!$D:$D,'PAGE_1 (2)'!$S$22)) | F24: =IF(SUMIFS(CNXL_SQL_2!$F:$F,CNXL_SQL_2!$A:$A,'PAGE_1 (2)'!$R24,CNXL_SQL_2!$D:$D,'PAGE_1 (2)'!$S$23)=0,"",SUMIFS(CNXL_SQL_2!$F:$F,CNXL_SQL_2!$A:$A,'PAGE_1 (2)'!$R24,CNXL_SQL_2!$D:$D,'PAGE_1 (2)'!$S$23)) | G24: =IF(SUMIFS(CNXL_SQL_2!$F:$F,CNXL_SQL_2!$A:$A,'PAGE_1 (2)'!$R24,CNXL_SQL_2!$D:$D,'PAGE_1 (2)'!$S$24)=0,"",SUMIFS(CNXL_SQL_2!$F:$F,CNXL_SQL_2!$A:$A,'PAGE_1 (2)'!$R24,CNXL_SQL_2!$D:$D,'PAGE_1 (2)'!$S$24)) | H24: =IF(SUMIFS(CNXL_SQL_2!$F:$F,CNXL_SQL_2!$A:$A,'PAGE_1 (2)'!$R24,CNXL_SQL_2!$D:$D,'PAGE_1 (2)'!$S$25)=0,"",SUMIFS(CNXL_SQL_2!$F:$F,CNXL_SQL_2!$A:$A,'PAGE_1 (2)'!$R24,CNXL_SQL_2!$D:$D,'PAGE_1 (2)'!$S$25)) | I24: =IF(SUMIFS(CNXL_SQL_2!$F:$F,CNXL_SQL_2!$A:$A,'PAGE_1 (2)'!$R24,CNXL_SQL_2!$D:$D,'PAGE_1 (2)'!$S$26)=0,"",SUMIFS(CNXL_SQL_2!$F:$F,CNXL_SQL_2!$A:$A,'PAGE_1 (2)'!$R24,CNXL_SQL_2!$D:$D,'PAGE_1 (2)'!$S$26)) | J24: =IF(SUMIFS(CNXL_SQL_2!$F:$F,CNXL_SQL_2!$A:$A,'PAGE_1 (2)'!$R24,CNXL_SQL_2!$D:$D,'PAGE_1 (2)'!$S$27)=0,"",SUMIFS(CNXL_SQL_2!$F:$F,CNXL_SQL_2!$A:$A,'PAGE_1 (2)'!$R24,CNXL_SQL_2!$D:$D,'PAGE_1 (2)'!$S$27)) | K24: =IF(SUMIFS(CNXL_SQL_2!$F:$F,CNXL_SQL_2!$A:$A,'PAGE_1 (2)'!$R24,CNXL_SQL_2!$D:$D,'PAGE_1 (2)'!$S$28)=0,"",SUMIFS(CNXL_SQL_2!$F:$F,CNXL_SQL_2!$A:$A,'PAGE_1 (2)'!$R24,CNXL_SQL_2!$D:$D,'PAGE_1 (2)'!$S$28)) | L24: =IF(SUMIFS(CNXL_SQL_2!$F:$F,CNXL_SQL_2!$A:$A,'PAGE_1 (2)'!$R24,CNXL_SQL_2!$D:$D,'PAGE_1 (2)'!$S$29)=0,"",SUMIFS(CNXL_SQL_2!$F:$F,CNXL_SQL_2!$A:$A,'PAGE_1 (2)'!$R24,CNXL_SQL_2!$D:$D,'PAGE_1 (2)'!$S$29)) | M24: =IF(SUM(D24:L24)=0,"",SUM(D24:L24)) | N24: =ES_MATRIX!K6 | O24: =IFERROR(M24-ES_MATRIX!L6,"") | P24: =IF(SUMIF(CNXL_SQL_2!$E:$E,'PAGE_1 (2)'!R24,CNXL_SQL_2!$F:$F)=0,"",SUMIF(CNXL_SQL_2!$E:$E,'PAGE_1 (2)'!R24,CNXL_SQL_2!$F:$F)) | R24: YX | S24: INFLIGHT SERVICES
B25: G7 - Go Jet | C25: =SUMIF(SCH_DEP_SQL_4!$A:$A,'PAGE_1 (2)'!R25,SCH_DEP_SQL_4!$E:$E) -> 186 | D25: =IF(SUMIFS(CNXL_SQL_2!$F:$F,CNXL_SQL_2!$A:$A,'PAGE_1 (2)'!$R25,CNXL_SQL_2!$D:$D,'PAGE_1 (2)'!$S$21)=0,"",SUMIFS(CNXL_SQL_2!$F:$F,CNXL_SQL_2!$A:$A,'PAGE_1 (2)'!$R25,CNXL_SQL_2!$D:$D,'PAGE_1 (2)'!$S$21)) | E25: =IF(SUMIFS(CNXL_SQL_2!$F:$F,CNXL_SQL_2!$A:$A,'PAGE_1 (2)'!$R25,CNXL_SQL_2!$D:$D,'PAGE_1 (2)'!$S$22)=0,"",SUMIFS(CNXL_SQL_2!$F:$F,CNXL_SQL_2!$A:$A,'PAGE_1 (2)'!$R25,CNXL_SQL_2!$D:$D,'PAGE_1 (2)'!$S$22)) | F25: =IF(SUMIFS(CNXL_SQL_2!$F:$F,CNXL_SQL_2!$A:$A,'PAGE_1 (2)'!$R25,CNXL_SQL_2!$D:$D,'PAGE_1 (2)'!$S$23)=0,"",SUMIFS(CNXL_SQL_2!$F:$F,CNXL_SQL_2!$A:$A,'PAGE_1 (2)'!$R25,CNXL_SQL_2!$D:$D,'PAGE_1 (2)'!$S$23)) | G25: =IF(SUMIFS(CNXL_SQL_2!$F:$F,CNXL_SQL_2!$A:$A,'PAGE_1 (2)'!$R25,CNXL_SQL_2!$D:$D,'PAGE_1 (2)'!$S$24)=0,"",SUMIFS(CNXL_SQL_2!$F:$F,CNXL_SQL_2!$A:$A,'PAGE_1 (2)'!$R25,CNXL_SQL_2!$D:$D,'PAGE_1 (2)'!$S$24)) | H25: =IF(SUMIFS(CNXL_SQL_2!$F:$F,CNXL_SQL_2!$A:$A,'PAGE_1 (2)'!$R25,CNXL_SQL_2!$D:$D,'PAGE_1 (2)'!$S$25)=0,"",SUMIFS(CNXL_SQL_2!$F:$F,CNXL_SQL_2!$A:$A,'PAGE_1 (2)'!$R25,CNXL_SQL_2!$D:$D,'PAGE_1 (2)'!$S$25)) | I25: =IF(SUMIFS(CNXL_SQL_2!$F:$F,CNXL_SQL_2!$A:$A,'PAGE_1 (2)'!$R25,CNXL_SQL_2!$D:$D,'PAGE_1 (2)'!$S$26)=0,"",SUMIFS(CNXL_SQL_2!$F:$F,CNXL_SQL_2!$A:$A,'PAGE_1 (2)'!$R25,CNXL_SQL_2!$D:$D,'PAGE_1 (2)'!$S$26)) | J25: =IF(SUMIFS(CNXL_SQL_2!$F:$F,CNXL_SQL_2!$A:$A,'PAGE_1 (2)'!$R25,CNXL_SQL_2!$D:$D,'PAGE_1 (2)'!$S$27)=0,"",SUMIFS(CNXL_SQL_2!$F:$F,CNXL_SQL_2!$A:$A,'PAGE_1 (2)'!$R25,CNXL_SQL_2!$D:$D,'PAGE_1 (2)'!$S$27)) | K25: =IF(SUMIFS(CNXL_SQL_2!$F:$F,CNXL_SQL_2!$A:$A,'PAGE_1 (2)'!$R25,CNXL_SQL_2!$D:$D,'PAGE_1 (2)'!$S$28)=0,"",SUMIFS(CNXL_SQL_2!$F:$F,CNXL_SQL_2!$A:$A,'PAGE_1 (2)'!$R25,CNXL_SQL_2!$D:$D,'PAGE_1 (2)'!$S$28)) | L25: =IF(SUMIFS(CNXL_SQL_2!$F:$F,CNXL_SQL_2!$A:$A,'PAGE_1 (2)'!$R25,CNXL_SQL_2!$D:$D,'PAGE_1 (2)'!$S$29)=0,"",SUMIFS(CNXL_SQL_2!$F:$F,CNXL_SQL_2!$A:$A,'PAGE_1 (2)'!$R25,CNXL_SQL_2!$D:$D,'PAGE_1 (2)'!$S$29)) | M25: =IF(SUM(D25:L25)=0,"",SUM(D25:L25)) | N25: =ES_MATRIX!K7 | O25: =IFERROR(M25-ES_MATRIX!L7,"") | P25: =IF(SUMIF(CNXL_SQL_2!$E:$E,'PAGE_1 (2)'!R25,CNXL_SQL_2!$F:$F)=0,"",SUMIF(CNXL_SQL_2!$E:$E,'PAGE_1 (2)'!R25,CNXL_SQL_2!$F:$F)) | R25: G7 | S25: AIRPORT OPERATIONS
B26: C5 - CommutAir | C26: =SUMIF(SCH_DEP_SQL_4!$A:$A,'PAGE_1 (2)'!R26,SCH_DEP_SQL_4!$E:$E) -> 193 | D26: =IF(SUMIFS(CNXL_SQL_2!$F:$F,CNXL_SQL_2!$A:$A,'PAGE_1 (2)'!$R26,CNXL_SQL_2!$D:$D,'PAGE_1 (2)'!$S$21)=0,"",SUMIFS(CNXL_SQL_2!$F:$F,CNXL_SQL_2!$A:$A,'PAGE_1 (2)'!$R26,CNXL_SQL_2!$D:$D,'PAGE_1 (2)'!$S$21)) -> 1 | E26: =IF(SUMIFS(CNXL_SQL_2!$F:$F,CNXL_SQL_2!$A:$A,'PAGE_1 (2)'!$R26,CNXL_SQL_2!$D:$D,'PAGE_1 (2)'!$S$22)=0,"",SUMIFS(CNXL_SQL_2!$F:$F,CNXL_SQL_2!$A:$A,'PAGE_1 (2)'!$R26,CNXL_SQL_2!$D:$D,'PAGE_1 (2)'!$S$22)) | F26: =IF(SUMIFS(CNXL_SQL_2!$F:$F,CNXL_SQL_2!$A:$A,'PAGE_1 (2)'!$R26,CNXL_SQL_2!$D:$D,'PAGE_1 (2)'!$S$23)=0,"",SUMIFS(CNXL_SQL_2!$F:$F,CNXL_SQL_2!$A:$A,'PAGE_1 (2)'!$R26,CNXL_SQL_2!$D:$D,'PAGE_1 (2)'!$S$23)) | G26: =IF(SUMIFS(CNXL_SQL_2!$F:$F,CNXL_SQL_2!$A:$A,'PAGE_1 (2)'!$R26,CNXL_SQL_2!$D:$D,'PAGE_1 (2)'!$S$24)=0,"",SUMIFS(CNXL_SQL_2!$F:$F,CNXL_SQL_2!$A:$A,'PAGE_1 (2)'!$R26,CNXL_SQL_2!$D:$D,'PAGE_1 (2)'!$S$24)) | H26: =IF(SUMIFS(CNXL_SQL_2!$F:$F,CNXL_SQL_2!$A:$A,'PAGE_1 (2)'!$R26,CNXL_SQL_2!$D:$D,'PAGE_1 (2)'!$S$25)=0,"",SUMIFS(CNXL_SQL_2!$F:$F,CNXL_SQL_2!$A:$A,'PAGE_1 (2)'!$R26,CNXL_SQL_2!$D:$D,'PAGE_1 (2)'!$S$25)) | I26: =IF(SUMIFS(CNXL_SQL_2!$F:$F,CNXL_SQL_2!$A:$A,'PAGE_1 (2)'!$R26,CNXL_SQL_2!$D:$D,'PAGE_1 (2)'!$S$26)=0,"",SUMIFS(CNXL_SQL_2!$F:$F,CNXL_SQL_2!$A:$A,'PAGE_1 (2)'!$R26,CNXL_SQL_2!$D:$D,'PAGE_1 (2)'!$S$26)) | J26: =IF(SUMIFS(CNXL_SQL_2!$F:$F,CNXL_SQL_2!$A:$A,'PAGE_1 (2)'!$R26,CNXL_SQL_2!$D:$D,'PAGE_1 (2)'!$S$27)=0,"",SUMIFS(CNXL_SQL_2!$F:$F,CNXL_SQL_2!$A:$A,'PAGE_1 (2)'!$R26,CNXL_SQL_2!$D:$D,'PAGE_1 (2)'!$S$27)) | K26: =IF(SUMIFS(CNXL_SQL_2!$F:$F,CNXL_SQL_2!$A:$A,'PAGE_1 (2)'!$R26,CNXL_SQL_2!$D:$D,'PAGE_1 (2)'!$S$28)=0,"",SUMIFS(CNXL_SQL_2!$F:$F,CNXL_SQL_2!$A:$A,'PAGE_1 (2)'!$R26,CNXL_SQL_2!$D:$D,'PAGE_1 (2)'!$S$28)) | L26: =IF(SUMIFS(CNXL_SQL_2!$F:$F,CNXL_SQL_2!$A:$A,'PAGE_1 (2)'!$R26,CNXL_SQL_2!$D:$D,'PAGE_1 (2)'!$S$29)=0,"",SUMIFS(CNXL_SQL_2!$F:$F,CNXL_SQL_2!$A:$A,'PAGE_1 (2)'!$R26,CNXL_SQL_2!$D:$D,'PAGE_1 (2)'!$S$29)) | M26: =IF(SUM(D26:L26)=0,"",SUM(D26:L26)) -> 1 | N26: =ES_MATRIX!K8 | O26: =IFERROR(M26-ES_MATRIX!L8,"") -> 1 | P26: =IF(SUMIF(CNXL_SQL_2!$E:$E,'PAGE_1 (2)'!R26,CNXL_SQL_2!$F:$F)=0,"",SUMIF(CNXL_SQL_2!$E:$E,'PAGE_1 (2)'!R26,CNXL_SQL_2!$F:$F)) | R26: C5 | S26: NETWORK OPERATIONS CENTER
B27: YV - Mesa | C27: =SUMIF(SCH_DEP_SQL_4!$A:$A,'PAGE_1 (2)'!R27,SCH_DEP_SQL_4!$E:$E) -> 213 | D27: =IF(SUMIFS(CNXL_SQL_2!$F:$F,CNXL_SQL_2!$A:$A,'PAGE_1 (2)'!$R27,CNXL_SQL_2!$D:$D,'PAGE_1 (2)'!$S$21)=0,"",SUMIFS(CNXL_SQL_2!$F:$F,CNXL_SQL_2!$A:$A,'PAGE_1 (2)'!$R27,CNXL_SQL_2!$D:$D,'PAGE_1 (2)'!$S$21)) | E27: =IF(SUMIFS(CNXL_SQL_2!$F:$F,CNXL_SQL_2!$A:$A,'PAGE_1 (2)'!$R27,CNXL_SQL_2!$D:$D,'PAGE_1 (2)'!$S$22)=0,"",SUMIFS(CNXL_SQL_2!$F:$F,CNXL_SQL_2!$A:$A,'PAGE_1 (2)'!$R27,CNXL_SQL_2!$D:$D,'PAGE_1 (2)'!$S$22)) | F27: =IF(SUMIFS(CNXL_SQL_2!$F:$F,CNXL_SQL_2!$A:$A,'PAGE_1 (2)'!$R27,CNXL_SQL_2!$D:$D,'PAGE_1 (2)'!$S$23)=0,"",SUMIFS(CNXL_SQL_2!$F:$F,CNXL_SQL_2!$A:$A,'PAGE_1 (2)'!$R27,CNXL_SQL_2!$D:$D,'PAGE_1 (2)'!$S$23)) | G27: =IF(SUMIFS(CNXL_SQL_2!$F:$F,CNXL_SQL_2!$A:$A,'PAGE_1 (2)'!$R27,CNXL_SQL_2!$D:$D,'PAGE_1 (2)'!$S$24)=0,"",SUMIFS(CNXL_SQL_2!$F:$F,CNXL_SQL_2!$A:$A,'PAGE_1 (2)'!$R27,CNXL_SQL_2!$D:$D,'PAGE_1 (2)'!$S$24)) | H27: =IF(SUMIFS(CNXL_SQL_2!$F:$F,CNXL_SQL_2!$A:$A,'PAGE_1 (2)'!$R27,CNXL_SQL_2!$D:$D,'PAGE_1 (2)'!$S$25)=0,"",SUMIFS(CNXL_SQL_2!$F:$F,CNXL_SQL_2!$A:$A,'PAGE_1 (2)'!$R27,CNXL_SQL_2!$D:$D,'PAGE_1 (2)'!$S$25)) | I27: =IF(SUMIFS(CNXL_SQL_2!$F:$F,CNXL_SQL_2!$A:$A,'PAGE_1 (2)'!$R27,CNXL_SQL_2!$D:$D,'PAGE_1 (2)'!$S$26)=0,"",SUMIFS(CNXL_SQL_2!$F:$F,CNXL_SQL_2!$A:$A,'PAGE_1 (2)'!$R27,CNXL_SQL_2!$D:$D,'PAGE_1 (2)'!$S$26)) | J27: =IF(SUMIFS(CNXL_SQL_2!$F:$F,CNXL_SQL_2!$A:$A,'PAGE_1 (2)'!$R27,CNXL_SQL_2!$D:$D,'PAGE_1 (2)'!$S$27)=0,"",SUMIFS(CNXL_SQL_2!$F:$F,CNXL_SQL_2!$A:$A,'PAGE_1 (2)'!$R27,CNXL_SQL_2!$D:$D,'PAGE_1 (2)'!$S$27)) | K27: =IF(SUMIFS(CNXL_SQL_2!$F:$F,CNXL_SQL_2!$A:$A,'PAGE_1 (2)'!$R27,CNXL_SQL_2!$D:$D,'PAGE_1 (2)'!$S$28)=0,"",SUMIFS(CNXL_SQL_2!$F:$F,CNXL_SQL_2!$A:$A,'PAGE_1 (2)'!$R27,CNXL_SQL_2!$D:$D,'PAGE_1 (2)'!$S$28)) | L27: =IF(SUMIFS(CNXL_SQL_2!$F:$F,CNXL_SQL_2!$A:$A,'PAGE_1 (2)'!$R27,CNXL_SQL_2!$D:$D,'PAGE_1 (2)'!$S$29)=0,"",SUMIFS(CNXL_SQL_2!$F:$F,CNXL_SQL_2!$A:$A,'PAGE_1 (2)'!$R27,CNXL_SQL_2!$D:$D,'PAGE_1 (2)'!$S$29)) | M27: =IF(SUM(D27:L27)=0,"",SUM(D27:L27)) | N27: =ES_MATRIX!K9 | O27: =IFERROR(M27-ES_MATRIX!L9,"") | P27: =IF(SUMIF(CNXL_SQL_2!$E:$E,'PAGE_1 (2)'!R27,CNXL_SQL_2!$F:$F)=0,"",SUMIF(CNXL_SQL_2!$E:$E,'PAGE_1 (2)'!R27,CNXL_SQL_2!$F:$F)) | R27: YV | S27: TECHNOLOGY
B28: ZW - Air Wisconsin | C28: =SUMIF(SCH_DEP_SQL_4!$A:$A,'PAGE_1 (2)'!R28,SCH_DEP_SQL_4!$E:$E) -> 0 | D28: =IF(SUMIFS(CNXL_SQL_2!$F:$F,CNXL_SQL_2!$A:$A,'PAGE_1 (2)'!$R28,CNXL_SQL_2!$D:$D,'PAGE_1 (2)'!$S$21)=0,"",SUMIFS(CNXL_SQL_2!$F:$F,CNXL_SQL_2!$A:$A,'PAGE_1 (2)'!$R28,CNXL_SQL_2!$D:$D,'PAGE_1 (2)'!$S$21)) | E28: =IF(SUMIFS(CNXL_SQL_2!$F:$F,CNXL_SQL_2!$A:$A,'PAGE_1 (2)'!$R28,CNXL_SQL_2!$D:$D,'PAGE_1 (2)'!$S$22)=0,"",SUMIFS(CNXL_SQL_2!$F:$F,CNXL_SQL_2!$A:$A,'PAGE_1 (2)'!$R28,CNXL_SQL_2!$D:$D,'PAGE_1 (2)'!$S$22)) | F28: =IF(SUMIFS(CNXL_SQL_2!$F:$F,CNXL_SQL_2!$A:$A,'PAGE_1 (2)'!$R28,CNXL_SQL_2!$D:$D,'PAGE_1 (2)'!$S$23)=0,"",SUMIFS(CNXL_SQL_2!$F:$F,CNXL_SQL_2!$A:$A,'PAGE_1 (2)'!$R28,CNXL_SQL_2!$D:$D,'PAGE_1 (2)'!$S$23)) | G28: =IF(SUMIFS(CNXL_SQL_2!$F:$F,CNXL_SQL_2!$A:$A,'PAGE_1 (2)'!$R28,CNXL_SQL_2!$D:$D,'PAGE_1 (2)'!$S$24)=0,"",SUMIFS(CNXL_SQL_2!$F:$F,CNXL_SQL_2!$A:$A,'PAGE_1 (2)'!$R28,CNXL_SQL_2!$D:$D,'PAGE_1 (2)'!$S$24)) | H28: =IF(SUMIFS(CNXL_SQL_2!$F:$F,CNXL_SQL_2!$A:$A,'PAGE_1 (2)'!$R28,CNXL_SQL_2!$D:$D,'PAGE_1 (2)'!$S$25)=0,"",SUMIFS(CNXL_SQL_2!$F:$F,CNXL_SQL_2!$A:$A,'PAGE_1 (2)'!$R28,CNXL_SQL_2!$D:$D,'PAGE_1 (2)'!$S$25)) | I28: =IF(SUMIFS(CNXL_SQL_2!$F:$F,CNXL_SQL_2!$A:$A,'PAGE_1 (2)'!$R28,CNXL_SQL_2!$D:$D,'PAGE_1 (2)'!$S$26)=0,"",SUMIFS(CNXL_SQL_2!$F:$F,CNXL_SQL_2!$A:$A,'PAGE_1 (2)'!$R28,CNXL_SQL_2!$D:$D,'PAGE_1 (2)'!$S$26)) | J28: =IF(SUMIFS(CNXL_SQL_2!$F:$F,CNXL_SQL_2!$A:$A,'PAGE_1 (2)'!$R28,CNXL_SQL_2!$D:$D,'PAGE_1 (2)'!$S$27)=0,"",SUMIFS(CNXL_SQL_2!$F:$F,CNXL_SQL_2!$A:$A,'PAGE_1 (2)'!$R28,CNXL_SQL_2!$D:$D,'PAGE_1 (2)'!$S$27)) | K28: =IF(SUMIFS(CNXL_SQL_2!$F:$F,CNXL_SQL_2!$A:$A,'PAGE_1 (2)'!$R28,CNXL_SQL_2!$D:$D,'PAGE_1 (2)'!$S$28)=0,"",SUMIFS(CNXL_SQL_2!$F:$F,CNXL_SQL_2!$A:$A,'PAGE_1 (2)'!$R28,CNXL_SQL_2!$D:$D,'PAGE_1 (2)'!$S$28)) | L28: =IF(SUMIFS(CNXL_SQL_2!$F:$F,CNXL_SQL_2!$A:$A,'PAGE_1 (2)'!$R28,CNXL_SQL_2!$D:$D,'PAGE_1 (2)'!$S$29)=0,"",SUMIFS(CNXL_SQL_2!$F:$F,CNXL_SQL_2!$A:$A,'PAGE_1 (2)'!$R28,CNXL_SQL_2!$D:$D,'PAGE_1 (2)'!$S$29)) | M28: =IF(SUM(D28:L28)=0,"",SUM(D28:L28)) | N28: =ES_MATRIX!K10 | O28: =IFERROR(M28-ES_MATRIX!L10,"") | P28: =IF(SUMIF(CNXL_SQL_2!$E:$E,'PAGE_1 (2)'!R28,CNXL_SQL_2!$F:$F)=0,"",SUMIF(CNXL_SQL_2!$E:$E,'PAGE_1 (2)'!R28,CNXL_SQL_2!$F:$F)) | R28: ZW | S28: CATERING OPERATIONS
B29: Total: | C29: =SUM(C21:C28) -> 1705 | D29: =IF(SUM(D21:D28)=0,"",SUM(D21:D28)) -> 11 | E29: =IF(SUM(E21:E28)=0,"",SUM(E21:E28)) | F29: =IF(SUM(F21:F28)=0,"",SUM(F21:F28)) | G29: =IF(SUM(G21:G28)=0,"",SUM(G21:G28)) | H29: =IF(SUM(H21:H28)=0,"",SUM(H21:H28)) | I29: =IF(SUM(I21:I28)=0,"",SUM(I21:I28)) | J29: =IF(SUM(J21:J28)=0,"",SUM(J21:J28)) | K29: =IF(SUM(K21:K28)=0,"",SUM(K21:K28)) | L29: =IF(SUM(L21:L28)=0,"",SUM(L21:L28)) | M29: =SUM(M21:M28) -> 11 | O29: =SUM(O21:O28) -> 11 | P29: =SUM(P21:P28) -> 0 | S29: OTHER
B33: Residual Cancel Detail
B34: Express Partner | C34: Scheduled Departures | D34: Weather & ATC | E34: Technical Operations | F34: Flight Operations | G34: Inflight Services | H34: Airport Operations | I34: Network Operations | J34: IT | K34: Catering Operations | L34: Other | M34: Total Cancels | N34: ES covered for this partner | O34: Net Cancel | P34: ES covered by this partner
B35: EV - ExpressJet | C35: =SUMIF(SCH_DEP_SQL_4!$A:$A,'PAGE_1 (2)'!R21,SCH_DEP_SQL_4!$E:$E) -> 0 | D35: =IF(SUMIFS(RES_CNXL_SQL_3!$F:$F,RES_CNXL_SQL_3!$A:$A,'PAGE_1 (2)'!$R21,RES_CNXL_SQL_3!$D:$D,'PAGE_1 (2)'!$S$21)=0,"",SUMIFS(RES_CNXL_SQL_3!$F:$F,RES_CNXL_SQL_3!$A:$A,'PAGE_1 (2)'!$R21,RES_CNXL_SQL_3!$D:$D,'PAGE_1 (2)'!$S$21)) | E35: =IF(SUMIFS(RES_CNXL_SQL_3!$F:$F,RES_CNXL_SQL_3!$A:$A,'PAGE_1 (2)'!$R21,RES_CNXL_SQL_3!$D:$D,'PAGE_1 (2)'!$S$22)=0,"",SUMIFS(RES_CNXL_SQL_3!$F:$F,RES_CNXL_SQL_3!$A:$A,'PAGE_1 (2)'!$R21,RES_CNXL_SQL_3!$D:$D,'PAGE_1 (2)'!$S$22)) | F35: =IF(SUMIFS(RES_CNXL_SQL_3!$F:$F,RES_CNXL_SQL_3!$A:$A,'PAGE_1 (2)'!$R21,RES_CNXL_SQL_3!$D:$D,'PAGE_1 (2)'!$S$23)=0,"",SUMIFS(RES_CNXL_SQL_3!$F:$F,RES_CNXL_SQL_3!$A:$A,'PAGE_1 (2)'!$R21,RES_CNXL_SQL_3!$D:$D,'PAGE_1 (2)'!$S$23)) | G35: =IF(SUMIFS(RES_CNXL_SQL_3!$F:$F,RES_CNXL_SQL_3!$A:$A,'PAGE_1 (2)'!$R21,RES_CNXL_SQL_3!$D:$D,'PAGE_1 (2)'!$S$24)=0,"",SUMIFS(RES_CNXL_SQL_3!$F:$F,RES_CNXL_SQL_3!$A:$A,'PAGE_1 (2)'!$R21,RES_CNXL_SQL_3!$D:$D,'PAGE_1 (2)'!$S$24)) | H35: =IF(SUMIFS(RES_CNXL_SQL_3!$F:$F,RES_CNXL_SQL_3!$A:$A,'PAGE_1 (2)'!$R21,RES_CNXL_SQL_3!$D:$D,'PAGE_1 (2)'!$S$25)=0,"",SUMIFS(RES_CNXL_SQL_3!$F:$F,RES_CNXL_SQL_3!$A:$A,'PAGE_1 (2)'!$R21,RES_CNXL_SQL_3!$D:$D,'PAGE_1 (2)'!$S$25)) | I35: =IF(SUMIFS(RES_CNXL_SQL_3!$F:$F,RES_CNXL_SQL_3!$A:$A,'PAGE_1 (2)'!$R21,RES_CNXL_SQL_3!$D:$D,'PAGE_1 (2)'!$S$26)=0,"",SUMIFS(RES_CNXL_SQL_3!$F:$F,RES_CNXL_SQL_3!$A:$A,'PAGE_1 (2)'!$R21,RES_CNXL_SQL_3!$D:$D,'PAGE_1 (2)'!$S$26)) | J35: =IF(SUMIFS(RES_CNXL_SQL_3!$F:$F,RES_CNXL_SQL_3!$A:$A,'PAGE_1 (2)'!$R21,RES_CNXL_SQL_3!$D:$D,'PAGE_1 (2)'!$S$27)=0,"",SUMIFS(RES_CNXL_SQL_3!$F:$F,RES_CNXL_SQL_3!$A:$A,'PAGE_1 (2)'!$R21,RES_CNXL_SQL_3!$D:$D,'PAGE_1 (2)'!$S$27)) | K35: =IF(SUMIFS(RES_CNXL_SQL_3!$F:$F,RES_CNXL_SQL_3!$A:$A,'PAGE_1 (2)'!$R21,RES_CNXL_SQL_3!$D:$D,'PAGE_1 (2)'!$S$28)=0,"",SUMIFS(RES_CNXL_SQL_3!$F:$F,RES_CNXL_SQL_3!$A:$A,'PAGE_1 (2)'!$R21,RES_CNXL_SQL_3!$D:$D,'PAGE_1 (2)'!$S$28)) | L35: =IF(SUMIFS(RES_CNXL_SQL_3!$F:$F,RES_CNXL_SQL_3!$A:$A,'PAGE_1 (2)'!$R21,RES_CNXL_SQL_3!$D:$D,'PAGE_1 (2)'!$S$29)=0,"",SUMIFS(RES_CNXL_SQL_3!$F:$F,RES_CNXL_SQL_3!$A:$A,'PAGE_1 (2)'!$R21,RES_CNXL_SQL_3!$D:$D,'PAGE_1 (2)'!$S$29)) | M35: =IF(SUM(D35:L35)=0,"",SUM(D35:L35)) | N35: =ES_MATRIX!K14 | O35: =IFERROR(M35-ES_MATRIX!L14,"") | P35: =IF(SUMIF(RES_CNXL_SQL_3!$E:$E,'PAGE_1 (2)'!R21,RES_CNXL_SQL_3!$F:$F)=0,"",SUMIF(RES_CNXL_SQL_3!$E:$E,'PAGE_1 (2)'!R21,RES_CNXL_SQL_3!$F:$F))
B36: OO - SkyWest | C36: =SUMIF(SCH_DEP_SQL_4!$A:$A,'PAGE_1 (2)'!R22,SCH_DEP_SQL_4!$E:$E) -> 816 | D36: =IF(SUMIFS(RES_CNXL_SQL_3!$F:$F,RES_CNXL_SQL_3!$A:$A,'PAGE_1 (2)'!$R22,RES_CNXL_SQL_3!$D:$D,'PAGE_1 (2)'!$S$21)=0,"",SUMIFS(RES_CNXL_SQL_3!$F:$F,RES_CNXL_SQL_3!$A:$A,'PAGE_1 (2)'!$R22,RES_CNXL_SQL_3!$D:$D,'PAGE_1 (2)'!$S$21)) -> 6 | E36: =IF(SUMIFS(RES_CNXL_SQL_3!$F:$F,RES_CNXL_SQL_3!$A:$A,'PAGE_1 (2)'!$R22,RES_CNXL_SQL_3!$D:$D,'PAGE_1 (2)'!$S$22)=0,"",SUMIFS(RES_CNXL_SQL_3!$F:$F,RES_CNXL_SQL_3!$A:$A,'PAGE_1 (2)'!$R22,RES_CNXL_SQL_3!$D:$D,'PAGE_1 (2)'!$S$22)) | F36: =IF(SUMIFS(RES_CNXL_SQL_3!$F:$F,RES_CNXL_SQL_3!$A:$A,'PAGE_1 (2)'!$R22,RES_CNXL_SQL_3!$D:$D,'PAGE_1 (2)'!$S$23)=0,"",SUMIFS(RES_CNXL_SQL_3!$F:$F,RES_CNXL_SQL_3!$A:$A,'PAGE_1 (2)'!$R22,RES_CNXL_SQL_3!$D:$D,'PAGE_1 (2)'!$S$23)) | G36: =IF(SUMIFS(RES_CNXL_SQL_3!$F:$F,RES_CNXL_SQL_3!$A:$A,'PAGE_1 (2)'!$R22,RES_CNXL_SQL_3!$D:$D,'PAGE_1 (2)'!$S$24)=0,"",SUMIFS(RES_CNXL_SQL_3!$F:$F,RES_CNXL_SQL_3!$A:$A,'PAGE_1 (2)'!$R22,RES_CNXL_SQL_3!$D:$D,'PAGE_1 (2)'!$S$24)) | H36: =IF(SUMIFS(RES_CNXL_SQL_3!$F:$F,RES_CNXL_SQL_3!$A:$A,'PAGE_1 (2)'!$R22,RES_CNXL_SQL_3!$D:$D,'PAGE_1 (2)'!$S$25)=0,"",SUMIFS(RES_CNXL_SQL_3!$F:$F,RES_CNXL_SQL_3!$A:$A,'PAGE_1 (2)'!$R22,RES_CNXL_SQL_3!$D:$D,'PAGE_1 (2)'!$S$25)) | I36: =IF(SUMIFS(RES_CNXL_SQL_3!$F:$F,RES_CNXL_SQL_3!$A:$A,'PAGE_1 (2)'!$R22,RES_CNXL_SQL_3!$D:$D,'PAGE_1 (2)'!$S$26)=0,"",SUMIFS(RES_CNXL_SQL_3!$F:$F,RES_CNXL_SQL_3!$A:$A,'PAGE_1 (2)'!$R22,RES_CNXL_SQL_3!$D:$D,'PAGE_1 (2)'!$S$26)) | J36: =IF(SUMIFS(RES_CNXL_SQL_3!$F:$F,RES_CNXL_SQL_3!$A:$A,'PAGE_1 (2)'!$R22,RES_CNXL_SQL_3!$D:$D,'PAGE_1 (2)'!$S$27)=0,"",SUMIFS(RES_CNXL_SQL_3!$F:$F,RES_CNXL_SQL_3!$A:$A,'PAGE_1 (2)'!$R22,RES_CNXL_SQL_3!$D:$D,'PAGE_1 (2)'!$S$27)) | K36: =IF(SUMIFS(RES_CNXL_SQL_3!$F:$F,RES_CNXL_SQL_3!$A:$A,'PAGE_1 (2)'!$R22,RES_CNXL_SQL_3!$D:$D,'PAGE_1 (2)'!$S$28)=0,"",SUMIFS(RES_CNXL_SQL_3!$F:$F,RES_CNXL_SQL_3!$A:$A,'PAGE_1 (2)'!$R22,RES_CNXL_SQL_3!$D:$D,'PAGE_1 (2)'!$S$28)) | L36: =IF(SUMIFS(RES_CNXL_SQL_3!$F:$F,RES_CNXL_SQL_3!$A:$A,'PAGE_1 (2)'!$R22,RES_CNXL_SQL_3!$D:$D,'PAGE_1 (2)'!$S$29)=0,"",SUMIFS(RES_CNXL_SQL_3!$F:$F,RES_CNXL_SQL_3!$A:$A,'PAGE_1 (2)'!$R22,RES_CNXL_SQL_3!$D:$D,'PAGE_1 (2)'!$S$29)) | M36: =IF(SUM(D36:L36)=0,"",SUM(D36:L36)) -> 6 | N36: =ES_MATRIX!K15 | O36: =IFERROR(M36-ES_MATRIX!L15,"") -> 6 | P36: =IF(SUMIF(RES_CNXL_SQL_3!$E:$E,'PAGE_1 (2)'!R22,RES_CNXL_SQL_3!$F:$F)=0,"",SUMIF(RES_CNXL_SQL_3!$E:$E,'PAGE_1 (2)'!R22,RES_CNXL_SQL_3!$F:$F))
B37: AX - Trans States | C37: =SUMIF(SCH_DEP_SQL_4!$A:$A,'PAGE_1 (2)'!R23,SCH_DEP_SQL_4!$E:$E) -> 0 | D37: =IF(SUMIFS(RES_CNXL_SQL_3!$F:$F,RES_CNXL_SQL_3!$A:$A,'PAGE_1 (2)'!$R23,RES_CNXL_SQL_3!$D:$D,'PAGE_1 (2)'!$S$21)=0,"",SUMIFS(RES_CNXL_SQL_3!$F:$F,RES_CNXL_SQL_3!$A:$A,'PAGE_1 (2)'!$R23,RES_CNXL_SQL_3!$D:$D,'PAGE_1 (2)'!$S$21)) | E37: =IF(SUMIFS(RES_CNXL_SQL_3!$F:$F,RES_CNXL_SQL_3!$A:$A,'PAGE_1 (2)'!$R23,RES_CNXL_SQL_3!$D:$D,'PAGE_1 (2)'!$S$22)=0,"",SUMIFS(RES_CNXL_SQL_3!$F:$F,RES_CNXL_SQL_3!$A:$A,'PAGE_1 (2)'!$R23,RES_CNXL_SQL_3!$D:$D,'PAGE_1 (2)'!$S$22)) | F37: =IF(SUMIFS(RES_CNXL_SQL_3!$F:$F,RES_CNXL_SQL_3!$A:$A,'PAGE_1 (2)'!$R23,RES_CNXL_SQL_3!$D:$D,'PAGE_1 (2)'!$S$23)=0,"",SUMIFS(RES_CNXL_SQL_3!$F:$F,RES_CNXL_SQL_3!$A:$A,'PAGE_1 (2)'!$R23,RES_CNXL_SQL_3!$D:$D,'PAGE_1 (2)'!$S$23)) | G37: =IF(SUMIFS(RES_CNXL_SQL_3!$F:$F,RES_CNXL_SQL_3!$A:$A,'PAGE_1 (2)'!$R23,RES_CNXL_SQL_3!$D:$D,'PAGE_1 (2)'!$S$24)=0,"",SUMIFS(RES_CNXL_SQL_3!$F:$F,RES_CNXL_SQL_3!$A:$A,'PAGE_1 (2)'!$R23,RES_CNXL_SQL_3!$D:$D,'PAGE_1 (2)'!$S$24)) | H37: =IF(SUMIFS(RES_CNXL_SQL_3!$F:$F,RES_CNXL_SQL_3!$A:$A,'PAGE_1 (2)'!$R23,RES_CNXL_SQL_3!$D:$D,'PAGE_1 (2)'!$S$25)=0,"",SUMIFS(RES_CNXL_SQL_3!$F:$F,RES_CNXL_SQL_3!$A:$A,'PAGE_1 (2)'!$R23,RES_CNXL_SQL_3!$D:$D,'PAGE_1 (2)'!$S$25)) | I37: =IF(SUMIFS(RES_CNXL_SQL_3!$F:$F,RES_CNXL_SQL_3!$A:$A,'PAGE_1 (2)'!$R23,RES_CNXL_SQL_3!$D:$D,'PAGE_1 (2)'!$S$26)=0,"",SUMIFS(RES_CNXL_SQL_3!$F:$F,RES_CNXL_SQL_3!$A:$A,'PAGE_1 (2)'!$R23,RES_CNXL_SQL_3!$D:$D,'PAGE_1 (2)'!$S$26)) | J37: =IF(SUMIFS(RES_CNXL_SQL_3!$F:$F,RES_CNXL_SQL_3!$A:$A,'PAGE_1 (2)'!$R23,RES_CNXL_SQL_3!$D:$D,'PAGE_1 (2)'!$S$27)=0,"",SUMIFS(RES_CNXL_SQL_3!$F:$F,RES_CNXL_SQL_3!$A:$A,'PAGE_1 (2)'!$R23,RES_CNXL_SQL_3!$D:$D,'PAGE_1 (2)'!$S$27)) | K37: =IF(SUMIFS(RES_CNXL_SQL_3!$F:$F,RES_CNXL_SQL_3!$A:$A,'PAGE_1 (2)'!$R23,RES_CNXL_SQL_3!$D:$D,'PAGE_1 (2)'!$S$28)=0,"",SUMIFS(RES_CNXL_SQL_3!$F:$F,RES_CNXL_SQL_3!$A:$A,'PAGE_1 (2)'!$R23,RES_CNXL_SQL_3!$D:$D,'PAGE_1 (2)'!$S$28)) | L37: =IF(SUMIFS(RES_CNXL_SQL_3!$F:$F,RES_CNXL_SQL_3!$A:$A,'PAGE_1 (2)'!$R23,RES_CNXL_SQL_3!$D:$D,'PAGE_1 (2)'!$S$29)=0,"",SUMIFS(RES_CNXL_SQL_3!$F:$F,RES_CNXL_SQL_3!$A:$A,'PAGE_1 (2)'!$R23,RES_CNXL_SQL_3!$D:$D,'PAGE_1 (2)'!$S$29)) | M37: =IF(SUM(D37:L37)=0,"",SUM(D37:L37)) | N37: =ES_MATRIX!K16 | O37: =IFERROR(M37-ES_MATRIX!L16,"") | P37: =IF(SUMIF(RES_CNXL_SQL_3!$E:$E,'PAGE_1 (2)'!R23,RES_CNXL_SQL_3!$F:$F)=0,"",SUMIF(RES_CNXL_SQL_3!$E:$E,'PAGE_1 (2)'!R23,RES_CNXL_SQL_3!$F:$F))
B38: YX - Republic | C38: =SUMIF(SCH_DEP_SQL_4!$A:$A,'PAGE_1 (2)'!R24,SCH_DEP_SQL_4!$E:$E) -> 297 | D38: =IF(SUMIFS(RES_CNXL_SQL_3!$F:$F,RES_CNXL_SQL_3!$A:$A,'PAGE_1 (2)'!$R24,RES_CNXL_SQL_3!$D:$D,'PAGE_1 (2)'!$S$21)=0,"",SUMIFS(RES_CNXL_SQL_3!$F:$F,RES_CNXL_SQL_3!$A:$A,'PAGE_1 (2)'!$R24,RES_CNXL_SQL_3!$D:$D,'PAGE_1 (2)'!$S$21)) | E38: =IF(SUMIFS(RES_CNXL_SQL_3!$F:$F,RES_CNXL_SQL_3!$A:$A,'PAGE_1 (2)'!$R24,RES_CNXL_SQL_3!$D:$D,'PAGE_1 (2)'!$S$22)=0,"",SUMIFS(RES_CNXL_SQL_3!$F:$F,RES_CNXL_SQL_3!$A:$A,'PAGE_1 (2)'!$R24,RES_CNXL_SQL_3!$D:$D,'PAGE_1 (2)'!$S$22)) | F38: =IF(SUMIFS(RES_CNXL_SQL_3!$F:$F,RES_CNXL_SQL_3!$A:$A,'PAGE_1 (2)'!$R24,RES_CNXL_SQL_3!$D:$D,'PAGE_1 (2)'!$S$23)=0,"",SUMIFS(RES_CNXL_SQL_3!$F:$F,RES_CNXL_SQL_3!$A:$A,'PAGE_1 (2)'!$R24,RES_CNXL_SQL_3!$D:$D,'PAGE_1 (2)'!$S$23)) | G38: =IF(SUMIFS(RES_CNXL_SQL_3!$F:$F,RES_CNXL_SQL_3!$A:$A,'PAGE_1 (2)'!$R24,RES_CNXL_SQL_3!$D:$D,'PAGE_1 (2)'!$S$24)=0,"",SUMIFS(RES_CNXL_SQL_3!$F:$F,RES_CNXL_SQL_3!$A:$A,'PAGE_1 (2)'!$R24,RES_CNXL_SQL_3!$D:$D,'PAGE_1 (2)'!$S$24)) | H38: =IF(SUMIFS(RES_CNXL_SQL_3!$F:$F,RES_CNXL_SQL_3!$A:$A,'PAGE_1 (2)'!$R24,RES_CNXL_SQL_3!$D:$D,'PAGE_1 (2)'!$S$25)=0,"",SUMIFS(RES_CNXL_SQL_3!$F:$F,RES_CNXL_SQL_3!$A:$A,'PAGE_1 (2)'!$R24,RES_CNXL_SQL_3!$D:$D,'PAGE_1 (2)'!$S$25)) | I38: =IF(SUMIFS(RES_CNXL_SQL_3!$F:$F,RES_CNXL_SQL_3!$A:$A,'PAGE_1 (2)'!$R24,RES_CNXL_SQL_3!$D:$D,'PAGE_1 (2)'!$S$26)=0,"",SUMIFS(RES_CNXL_SQL_3!$F:$F,RES_CNXL_SQL_3!$A:$A,'PAGE_1 (2)'!$R24,RES_CNXL_SQL_3!$D:$D,'PAGE_1 (2)'!$S$26)) | J38: =IF(SUMIFS(RES_CNXL_SQL_3!$F:$F,RES_CNXL_SQL_3!$A:$A,'PAGE_1 (2)'!$R24,RES_CNXL_SQL_3!$D:$D,'PAGE_1 (2)'!$S$27)=0,"",SUMIFS(RES_CNXL_SQL_3!$F:$F,RES_CNXL_SQL_3!$A:$A,'PAGE_1 (2)'!$R24,RES_CNXL_SQL_3!$D:$D,'PAGE_1 (2)'!$S$27)) | K38: =IF(SUMIFS(RES_CNXL_SQL_3!$F:$F,RES_CNXL_SQL_3!$A:$A,'PAGE_1 (2)'!$R24,RES_CNXL_SQL_3!$D:$D,'PAGE_1 (2)'!$S$28)=0,"",SUMIFS(RES_CNXL_SQL_3!$F:$F,RES_CNXL_SQL_3!$A:$A,'PAGE_1 (2)'!$R24,RES_CNXL_SQL_3!$D:$D,'PAGE_1 (2)'!$S$28)) | L38: =IF(SUMIFS(RES_CNXL_SQL_3!$F:$F,RES_CNXL_SQL_3!$A:$A,'PAGE_1 (2)'!$R24,RES_CNXL_SQL_3!$D:$D,'PAGE_1 (2)'!$S$29)=0,"",SUMIFS(RES_CNXL_SQL_3!$F:$F,RES_CNXL_SQL_3!$A:$A,'PAGE_1 (2)'!$R24,RES_CNXL_SQL_3!$D:$D,'PAGE_1 (2)'!$S$29)) | M38: =IF(SUM(D38:L38)=0,"",SUM(D38:L38)) | N38: =ES_MATRIX!K17 | O38: =IFERROR(M38-ES_MATRIX!L17,"") | P38: =IF(SUMIF(RES_CNXL_SQL_3!$E:$E,'PAGE_1 (2)'!R24,RES_CNXL_SQL_3!$F:$F)=0,"",SUMIF(RES_CNXL_SQL_3!$E:$E,'PAGE_1 (2)'!R24,RES_CNXL_SQL_3!$F:$F))
B39: G7 - Go Jet | C39: =SUMIF(SCH_DEP_SQL_4!$A:$A,'PAGE_1 (2)'!R25,SCH_DEP_SQL_4!$E:$E) -> 186 | D39: =IF(SUMIFS(RES_CNXL_SQL_3!$F:$F,RES_CNXL_SQL_3!$A:$A,'PAGE_1 (2)'!$R25,RES_CNXL_SQL_3!$D:$D,'PAGE_1 (2)'!$S$21)=0,"",SUMIFS(RES_CNXL_SQL_3!$F:$F,RES_CNXL_SQL_3!$A:$A,'PAGE_1 (2)'!$R25,RES_CNXL_SQL_3!$D:$D,'PAGE_1 (2)'!$S$21)) | E39: =IF(SUMIFS(RES_CNXL_SQL_3!$F:$F,RES_CNXL_SQL_3!$A:$A,'PAGE_1 (2)'!$R25,RES_CNXL_SQL_3!$D:$D,'PAGE_1 (2)'!$S$22)=0,"",SUMIFS(RES_CNXL_SQL_3!$F:$F,RES_CNXL_SQL_3!$A:$A,'PAGE_1 (2)'!$R25,RES_CNXL_SQL_3!$D:$D,'PAGE_1 (2)'!$S$22)) | F39: =IF(SUMIFS(RES_CNXL_SQL_3!$F:$F,RES_CNXL_SQL_3!$A:$A,'PAGE_1 (2)'!$R25,RES_CNXL_SQL_3!$D:$D,'PAGE_1 (2)'!$S$23)=0,"",SUMIFS(RES_CNXL_SQL_3!$F:$F,RES_CNXL_SQL_3!$A:$A,'PAGE_1 (2)'!$R25,RES_CNXL_SQL_3!$D:$D,'PAGE_1 (2)'!$S$23)) | G39: =IF(SUMIFS(RES_CNXL_SQL_3!$F:$F,RES_CNXL_SQL_3!$A:$A,'PAGE_1 (2)'!$R25,RES_CNXL_SQL_3!$D:$D,'PAGE_1 (2)'!$S$24)=0,"",SUMIFS(RES_CNXL_SQL_3!$F:$F,RES_CNXL_SQL_3!$A:$A,'PAGE_1 (2)'!$R25,RES_CNXL_SQL_3!$D:$D,'PAGE_1 (2)'!$S$24)) | H39: =IF(SUMIFS(RES_CNXL_SQL_3!$F:$F,RES_CNXL_SQL_3!$A:$A,'PAGE_1 (2)'!$R25,RES_CNXL_SQL_3!$D:$D,'PAGE_1 (2)'!$S$25)=0,"",SUMIFS(RES_CNXL_SQL_3!$F:$F,RES_CNXL_SQL_3!$A:$A,'PAGE_1 (2)'!$R25,RES_CNXL_SQL_3!$D:$D,'PAGE_1 (2)'!$S$25)) -> 1 | I39: =IF(SUMIFS(RES_CNXL_SQL_3!$F:$F,RES_CNXL_SQL_3!$A:$A,'PAGE_1 (2)'!$R25,RES_CNXL_SQL_3!$D:$D,'PAGE_1 (2)'!$S$26)=0,"",SUMIFS(RES_CNXL_SQL_3!$F:$F,RES_CNXL_SQL_3!$A:$A,'PAGE_1 (2)'!$R25,RES_CNXL_SQL_3!$D:$D,'PAGE_1 (2)'!$S$26)) | J39: =IF(SUMIFS(RES_CNXL_SQL_3!$F:$F,RES_CNXL_SQL_3!$A:$A,'PAGE_1 (2)'!$R25,RES_CNXL_SQL_3!$D:$D,'PAGE_1 (2)'!$S$27)=0,"",SUMIFS(RES_CNXL_SQL_3!$F:$F,RES_CNXL_SQL_3!$A:$A,'PAGE_1 (2)'!$R25,RES_CNXL_SQL_3!$D:$D,'PAGE_1 (2)'!$S$27)) | K39: =IF(SUMIFS(RES_CNXL_SQL_3!$F:$F,RES_CNXL_SQL_3!$A:$A,'PAGE_1 (2)'!$R25,RES_CNXL_SQL_3!$D:$D,'PAGE_1 (2)'!$S$28)=0,"",SUMIFS(RES_CNXL_SQL_3!$F:$F,RES_CNXL_SQL_3!$A:$A,'PAGE_1 (2)'!$R25,RES_CNXL_SQL_3!$D:$D,'PAGE_1 (2)'!$S$28)) | L39: =IF(SUMIFS(RES_CNXL_SQL_3!$F:$F,RES_CNXL_SQL_3!$A:$A,'PAGE_1 (2)'!$R25,RES_CNXL_SQL_3!$D:$D,'PAGE_1 (2)'!$S$29)=0,"",SUMIFS(RES_CNXL_SQL_3!$F:$F,RES_CNXL_SQL_3!$A:$A,'PAGE_1 (2)'!$R25,RES_CNXL_SQL_3!$D:$D,'PAGE_1 (2)'!$S$29)) | M39: =IF(SUM(D39:L39)=0,"",SUM(D39:L39)) -> 1 | N39: =ES_MATRIX!K18 | O39: =IFERROR(M39-ES_MATRIX!L18,"") -> 1 | P39: =IF(SUMIF(RES_CNXL_SQL_3!$E:$E,'PAGE_1 (2)'!R25,RES_CNXL_SQL_3!$F:$F)=0,"",SUMIF(RES_CNXL_SQL_3!$E:$E,'PAGE_1 (2)'!R25,RES_CNXL_SQL_3!$F:$F))
B40: C5 - CommutAir | C40: =SUMIF(SCH_DEP_SQL_4!$A:$A,'PAGE_1 (2)'!R26,SCH_DEP_SQL_4!$E:$E) -> 193 | D40: =IF(SUMIFS(RES_CNXL_SQL_3!$F:$F,RES_CNXL_SQL_3!$A:$A,'PAGE_1 (2)'!$R26,RES_CNXL_SQL_3!$D:$D,'PAGE_1 (2)'!$S$21)=0,"",SUMIFS(RES_CNXL_SQL_3!$F:$F,RES_CNXL_SQL_3!$A:$A,'PAGE_1 (2)'!$R26,RES_CNXL_SQL_3!$D:$D,'PAGE_1 (2)'!$S$21)) | E40: =IF(SUMIFS(RES_CNXL_SQL_3!$F:$F,RES_CNXL_SQL_3!$A:$A,'PAGE_1 (2)'!$R26,RES_CNXL_SQL_3!$D:$D,'PAGE_1 (2)'!$S$22)=0,"",SUMIFS(RES_CNXL_SQL_3!$F:$F,RES_CNXL_SQL_3!$A:$A,'PAGE_1 (2)'!$R26,RES_CNXL_SQL_3!$D:$D,'PAGE_1 (2)'!$S$22)) | F40: =IF(SUMIFS(RES_CNXL_SQL_3!$F:$F,RES_CNXL_SQL_3!$A:$A,'PAGE_1 (2)'!$R26,RES_CNXL_SQL_3!$D:$D,'PAGE_1 (2)'!$S$23)=0,"",SUMIFS(RES_CNXL_SQL_3!$F:$F,RES_CNXL_SQL_3!$A:$A,'PAGE_1 (2)'!$R26,RES_CNXL_SQL_3!$D:$D,'PAGE_1 (2)'!$S$23)) | G40: =IF(SUMIFS(RES_CNXL_SQL_3!$F:$F,RES_CNXL_SQL_3!$A:$A,'PAGE_1 (2)'!$R26,RES_CNXL_SQL_3!$D:$D,'PAGE_1 (2)'!$S$24)=0,"",SUMIFS(RES_CNXL_SQL_3!$F:$F,RES_CNXL_SQL_3!$A:$A,'PAGE_1 (2)'!$R26,RES_CNXL_SQL_3!$D:$D,'PAGE_1 (2)'!$S$24)) | H40: =IF(SUMIFS(RES_CNXL_SQL_3!$F:$F,RES_CNXL_SQL_3!$A:$A,'PAGE_1 (2)'!$R26,RES_CNXL_SQL_3!$D:$D,'PAGE_1 (2)'!$S$25)=0,"",SUMIFS(RES_CNXL_SQL_3!$F:$F,RES_CNXL_SQL_3!$A:$A,'PAGE_1 (2)'!$R26,RES_CNXL_SQL_3!$D:$D,'PAGE_1 (2)'!$S$25)) | I40: =IF(SUMIFS(RES_CNXL_SQL_3!$F:$F,RES_CNXL_SQL_3!$A:$A,'PAGE_1 (2)'!$R26,RES_CNXL_SQL_3!$D:$D,'PAGE_1 (2)'!$S$26)=0,"",SUMIFS(RES_CNXL_SQL_3!$F:$F,RES_CNXL_SQL_3!$A:$A,'PAGE_1 (2)'!$R26,RES_CNXL_SQL_3!$D:$D,'PAGE_1 (2)'!$S$26)) | J40: =IF(SUMIFS(RES_CNXL_SQL_3!$F:$F,RES_CNXL_SQL_3!$A:$A,'PAGE_1 (2)'!$R26,RES_CNXL_SQL_3!$D:$D,'PAGE_1 (2)'!$S$27)=0,"",SUMIFS(RES_CNXL_SQL_3!$F:$F,RES_CNXL_SQL_3!$A:$A,'PAGE_1 (2)'!$R26,RES_CNXL_SQL_3!$D:$D,'PAGE_1 (2)'!$S$27)) | K40: =IF(SUMIFS(RES_CNXL_SQL_3!$F:$F,RES_CNXL_SQL_3!$A:$A,'PAGE_1 (2)'!$R26,RES_CNXL_SQL_3!$D:$D,'PAGE_1 (2)'!$S$28)=0,"",SUMIFS(RES_CNXL_SQL_3!$F:$F,RES_CNXL_SQL_3!$A:$A,'PAGE_1 (2)'!$R26,RES_CNXL_SQL_3!$D:$D,'PAGE_1 (2)'!$S$28)) | L40: =IF(SUMIFS(RES_CNXL_SQL_3!$F:$F,RES_CNXL_SQL_3!$A:$A,'PAGE_1 (2)'!$R26,RES_CNXL_SQL_3!$D:$D,'PAGE_1 (2)'!$S$29)=0,"",SUMIFS(RES_CNXL_SQL_3!$F:$F,RES_CNXL_SQL_3!$A:$A,'PAGE_1 (2)'!$R26,RES_CNXL_SQL_3!$D:$D,'PAGE_1 (2)'!$S$29)) | M40: =IF(SUM(D40:L40)=0,"",SUM(D40:L40)) | N40: =ES_MATRIX!K19 | O40: =IFERROR(M40-ES_MATRIX!L19,"") | P40: =IF(SUMIF(RES_CNXL_SQL_3!$E:$E,'PAGE_1 (2)'!R26,RES_CNXL_SQL_3!$F:$F)=0,"",SUMIF(RES_CNXL_SQL_3!$E:$E,'PAGE_1 (2)'!R26,RES_CNXL_SQL_3!$F:$F))
B41: YV - Mesa | C41: =SUMIF(SCH_DEP_SQL_4!$A:$A,'PAGE_1 (2)'!R27,SCH_DEP_SQL_4!$E:$E) -> 213 | D41: =IF(SUMIFS(RES_CNXL_SQL_3!$F:$F,RES_CNXL_SQL_3!$A:$A,'PAGE_1 (2)'!$R27,RES_CNXL_SQL_3!$D:$D,'PAGE_1 (2)'!$S$21)=0,"",SUMIFS(RES_CNXL_SQL_3!$F:$F,RES_CNXL_SQL_3!$A:$A,'PAGE_1 (2)'!$R27,RES_CNXL_SQL_3!$D:$D,'PAGE_1 (2)'!$S$21)) | E41: =IF(SUMIFS(RES_CNXL_SQL_3!$F:$F,RES_CNXL_SQL_3!$A:$A,'PAGE_1 (2)'!$R27,RES_CNXL_SQL_3!$D:$D,'PAGE_1 (2)'!$S$22)=0,"",SUMIFS(RES_CNXL_SQL_3!$F:$F,RES_CNXL_SQL_3!$A:$A,'PAGE_1 (2)'!$R27,RES_CNXL_SQL_3!$D:$D,'PAGE_1 (2)'!$S$22)) | F41: =IF(SUMIFS(RES_CNXL_SQL_3!$F:$F,RES_CNXL_SQL_3!$A:$A,'PAGE_1 (2)'!$R27,RES_CNXL_SQL_3!$D:$D,'PAGE_1 (2)'!$S$23)=0,"",SUMIFS(RES_CNXL_SQL_3!$F:$F,RES_CNXL_SQL_3!$A:$A,'PAGE_1 (2)'!$R27,RES_CNXL_SQL_3!$D:$D,'PAGE_1 (2)'!$S$23)) | G41: =IF(SUMIFS(RES_CNXL_SQL_3!$F:$F,RES_CNXL_SQL_3!$A:$A,'PAGE_1 (2)'!$R27,RES_CNXL_SQL_3!$D:$D,'PAGE_1 (2)'!$S$24)=0,"",SUMIFS(RES_CNXL_SQL_3!$F:$F,RES_CNXL_SQL_3!$A:$A,'PAGE_1 (2)'!$R27,RES_CNXL_SQL_3!$D:$D,'PAGE_1 (2)'!$S$24)) | H41: =IF(SUMIFS(RES_CNXL_SQL_3!$F:$F,RES_CNXL_SQL_3!$A:$A,'PAGE_1 (2)'!$R27,RES_CNXL_SQL_3!$D:$D,'PAGE_1 (2)'!$S$25)=0,"",SUMIFS(RES_CNXL_SQL_3!$F:$F,RES_CNXL_SQL_3!$A:$A,'PAGE_1 (2)'!$R27,RES_CNXL_SQL_3!$D:$D,'PAGE_1 (2)'!$S$25)) | I41: =IF(SUMIFS(RES_CNXL_SQL_3!$F:$F,RES_CNXL_SQL_3!$A:$A,'PAGE_1 (2)'!$R27,RES_CNXL_SQL_3!$D:$D,'PAGE_1 (2)'!$S$26)=0,"",SUMIFS(RES_CNXL_SQL_3!$F:$F,RES_CNXL_SQL_3!$A:$A,'PAGE_1 (2)'!$R27,RES_CNXL_SQL_3!$D:$D,'PAGE_1 (2)'!$S$26)) | J41: =IF(SUMIFS(RES_CNXL_SQL_3!$F:$F,RES_CNXL_SQL_3!$A:$A,'PAGE_1 (2)'!$R27,RES_CNXL_SQL_3!$D:$D,'PAGE_1 (2)'!$S$27)=0,"",SUMIFS(RES_CNXL_SQL_3!$F:$F,RES_CNXL_SQL_3!$A:$A,'PAGE_1 (2)'!$R27,RES_CNXL_SQL_3!$D:$D,'PAGE_1 (2)'!$S$27)) | K41: =IF(SUMIFS(RES_CNXL_SQL_3!$F:$F,RES_CNXL_SQL_3!$A:$A,'PAGE_1 (2)'!$R27,RES_CNXL_SQL_3!$D:$D,'PAGE_1 (2)'!$S$28)=0,"",SUMIFS(RES_CNXL_SQL_3!$F:$F,RES_CNXL_SQL_3!$A:$A,'PAGE_1 (2)'!$R27,RES_CNXL_SQL_3!$D:$D,'PAGE_1 (2)'!$S$28)) | L41: =IF(SUMIFS(RES_CNXL_SQL_3!$F:$F,RES_CNXL_SQL_3!$A:$A,'PAGE_1 (2)'!$R27,RES_CNXL_SQL_3!$D:$D,'PAGE_1 (2)'!$S$29)=0,"",SUMIFS(RES_CNXL_SQL_3!$F:$F,RES_CNXL_SQL_3!$A:$A,'PAGE_1 (2)'!$R27,RES_CNXL_SQL_3!$D:$D,'PAGE_1 (2)'!$S$29)) | M41: =IF(SUM(D41:L41)=0,"",SUM(D41:L41)) | N41: =ES_MATRIX!K20 | O41: =IFERROR(M41-ES_MATRIX!L20,"") | P41: =IF(SUMIF(RES_CNXL_SQL_3!$E:$E,'PAGE_1 (2)'!R27,RES_CNXL_SQL_3!$F:$F)=0,"",SUMIF(RES_CNXL_SQL_3!$E:$E,'PAGE_1 (2)'!R27,RES_CNXL_SQL_3!$F:$F))
B42: ZW - Air Wisconsin | C42: =SUMIF(SCH_DEP_SQL_4!$A:$A,'PAGE_1 (2)'!R28,SCH_DEP_SQL_4!$E:$E) -> 0 | D42: =IF(SUMIFS(RES_CNXL_SQL_3!$F:$F,RES_CNXL_SQL_3!$A:$A,'PAGE_1 (2)'!$R28,RES_CNXL_SQL_3!$D:$D,'PAGE_1 (2)'!$S$21)=0,"",SUMIFS(RES_CNXL_SQL_3!$F:$F,RES_CNXL_SQL_3!$A:$A,'PAGE_1 (2)'!$R28,RES_CNXL_SQL_3!$D:$D,'PAGE_1 (2)'!$S$21)) | E42: =IF(SUMIFS(RES_CNXL_SQL_3!$F:$F,RES_CNXL_SQL_3!$A:$A,'PAGE_1 (2)'!$R28,RES_CNXL_SQL_3!$D:$D,'PAGE_1 (2)'!$S$22)=0,"",SUMIFS(RES_CNXL_SQL_3!$F:$F,RES_CNXL_SQL_3!$A:$A,'PAGE_1 (2)'!$R28,RES_CNXL_SQL_3!$D:$D,'PAGE_1 (2)'!$S$22)) | F42: =IF(SUMIFS(RES_CNXL_SQL_3!$F:$F,RES_CNXL_SQL_3!$A:$A,'PAGE_1 (2)'!$R28,RES_CNXL_SQL_3!$D:$D,'PAGE_1 (2)'!$S$23)=0,"",SUMIFS(RES_CNXL_SQL_3!$F:$F,RES_CNXL_SQL_3!$A:$A,'PAGE_1 (2)'!$R28,RES_CNXL_SQL_3!$D:$D,'PAGE_1 (2)'!$S$23)) | G42: =IF(SUMIFS(RES_CNXL_SQL_3!$F:$F,RES_CNXL_SQL_3!$A:$A,'PAGE_1 (2)'!$R28,RES_CNXL_SQL_3!$D:$D,'PAGE_1 (2)'!$S$24)=0,"",SUMIFS(RES_CNXL_SQL_3!$F:$F,RES_CNXL_SQL_3!$A:$A,'PAGE_1 (2)'!$R28,RES_CNXL_SQL_3!$D:$D,'PAGE_1 (2)'!$S$24)) | H42: =IF(SUMIFS(RES_CNXL_SQL_3!$F:$F,RES_CNXL_SQL_3!$A:$A,'PAGE_1 (2)'!$R28,RES_CNXL_SQL_3!$D:$D,'PAGE_1 (2)'!$S$25)=0,"",SUMIFS(RES_CNXL_SQL_3!$F:$F,RES_CNXL_SQL_3!$A:$A,'PAGE_1 (2)'!$R28,RES_CNXL_SQL_3!$D:$D,'PAGE_1 (2)'!$S$25)) | I42: =IF(SUMIFS(RES_CNXL_SQL_3!$F:$F,RES_CNXL_SQL_3!$A:$A,'PAGE_1 (2)'!$R28,RES_CNXL_SQL_3!$D:$D,'PAGE_1 (2)'!$S$26)=0,"",SUMIFS(RES_CNXL_SQL_3!$F:$F,RES_CNXL_SQL_3!$A:$A,'PAGE_1 (2)'!$R28,RES_CNXL_SQL_3!$D:$D,'PAGE_1 (2)'!$S$26)) | J42: =IF(SUMIFS(RES_CNXL_SQL_3!$F:$F,RES_CNXL_SQL_3!$A:$A,'PAGE_1 (2)'!$R28,RES_CNXL_SQL_3!$D:$D,'PAGE_1 (2)'!$S$27)=0,"",SUMIFS(RES_CNXL_SQL_3!$F:$F,RES_CNXL_SQL_3!$A:$A,'PAGE_1 (2)'!$R28,RES_CNXL_SQL_3!$D:$D,'PAGE_1 (2)'!$S$27)) | K42: =IF(SUMIFS(RES_CNXL_SQL_3!$F:$F,RES_CNXL_SQL_3!$A:$A,'PAGE_1 (2)'!$R28,RES_CNXL_SQL_3!$D:$D,'PAGE_1 (2)'!$S$28)=0,"",SUMIFS(RES_CNXL_SQL_3!$F:$F,RES_CNXL_SQL_3!$A:$A,'PAGE_1 (2)'!$R28,RES_CNXL_SQL_3!$D:$D,'PAGE_1 (2)'!$S$28)) | L42: =IF(SUMIFS(RES_CNXL_SQL_3!$F:$F,RES_CNXL_SQL_3!$A:$A,'PAGE_1 (2)'!$R28,RES_CNXL_SQL_3!$D:$D,'PAGE_1 (2)'!$S$29)=0,"",SUMIFS(RES_CNXL_SQL_3!$F:$F,RES_CNXL_SQL_3!$A:$A,'PAGE_1 (2)'!$R28,RES_CNXL_SQL_3!$D:$D,'PAGE_1 (2)'!$S$29)) | M42: =IF(SUM(D42:L42)=0,"",SUM(D42:L42)) | N42: =ES_MATRIX!K21 | O42: =IFERROR(M42-ES_MATRIX!L21,"") | P42: =IF(SUMIF(RES_CNXL_SQL_3!$E:$E,'PAGE_1 (2)'!R28,RES_CNXL_SQL_3!$F:$F)=0,"",SUMIF(RES_CNXL_SQL_3!$E:$E,'PAGE_1 (2)'!R28,RES_CNXL_SQL_3!$F:$F))
B43: Total: | C43: =SUM(C35:C42) -> 1705 | D43: =IF(SUM(D35:D42)=0,"",SUM(D35:D42)) -> 6 | E43: =IF(SUM(E35:E42)=0,"",SUM(E35:E42)) | F43: =IF(SUM(F35:F42)=0,"",SUM(F35:F42)) | G43: =IF(SUM(G35:G42)=0,"",SUM(G35:G42)) | H43: =IF(SUM(H35:H42)=0,"",SUM(H35:H42)) -> 1 | I43: =IF(SUM(I35:I42)=0,"",SUM(I35:I42)) | J43: =IF(SUM(J35:J42)=0,"",SUM(J35:J42)) | K43: =IF(SUM(K35:K42)=0,"",SUM(K35:K42)) | L43: =IF(SUM(L35:L42)=0,"",SUM(L35:L42)) | M43: =SUM(M35:M42) -> 7 | O43: =SUM(O35:O42) -> 7 | P43: =SUM(P35:P42) -> 0

Sheet PAGE_1 (4)
B2: UAX Daily Snapshot for | D2: =TODAY()-1 -> 45644
B4: Reliability Snapshot - SYS
B5: Metric | C5: =TODAY()-1 -> 45644 | D5: MTD | E5: Goal | F5: DL Diff. | G5: AA Diff. | H5: Rank
B6: Completion | C6: =UA_SQL_1!N2/UA_SQL_1!M2 -> 852.5 | D6: =UA_SQL_1!F2/UA_SQL_1!E2 -> 0.0040492958 | E6: =SUMIF(EX_Goals!$B:$B,'PAGE_1 (4)'!#REF!,EX_Goals!$E:$E) -> 0 | F6: =((UA_SQL_1!$N$2/UA_SQL_1!$M$2)-(SUMIF(OA_SQL_1!$A$1:$A$3,"DL",OA_SQL_1!$K$1:$K$3)/SUMIF(OA_SQL_1!$A$1:$A$3,"DL",OA_SQL_1!$I$1:$I$3)))*100 -> 85218.586 | G6: =((UA_SQL_1!$N$2/UA_SQL_1!$M$2)-(SUMIF(OA_SQL_1!$A$1:$A$3,"AA",OA_SQL_1!$K$1:$K$3)/SUMIF(OA_SQL_1!$A$1:$A$3,"AA",OA_SQL_1!$I$1:$I$3)))*100 -> 85221.573 | H6: =RANK!F2 -> 3
B7: A:00 | C7: =UA_SQL_1!Q2/UA_SQL_1!M2 -> 665.5 | D7: =UA_SQL_1!I2/UA_SQL_1!E2 -> 0.6415493 | E7: =SUMIF(EX_Goals!$B:$B,'PAGE_1 (4)'!#REF!,EX_Goals!$D:$D) -> 0 | F7: =((UA_SQL_1!$Q$2/UA_SQL_1!$M$2)-(SUMIF(OA_SQL_1!$A$1:$A$3,"DL",OA_SQL_1!$L$1:$L$3)/SUMIF(OA_SQL_1!$A$1:$A$3,"DL",OA_SQL_1!$I$1:$I$3)))*100 -> 66504.526 | G7: =((UA_SQL_1!$Q$2/UA_SQL_1!$M$2)-(SUMIF(OA_SQL_1!$A$1:$A$3,"AA",OA_SQL_1!$L$1:$L$3)/SUMIF(OA_SQL_1!$A$1:$A$3,"AA",OA_SQL_1!$I$1:$I$3)))*100 -> 66511.17 | H7: =RANK!F3 -> 1
B8: CS D:00 | C8: =UA_SQL_1!P2/UA_SQL_1!M2 -> 648.5 | D8: =UA_SQL_1!H2/UA_SQL_1!E2 -> 0.71795775 | E8: =SUMIF(EX_Goals!$B:$B,'PAGE_1 (4)'!#REF!,EX_Goals!$C:$C) -> 0 | F8: =((UA_SQL_1!$P$2/UA_SQL_1!$M$2)-(SUMIF(OA_SQL_1!$A$1:$A$3,"DL",OA_SQL_1!$J$1:$J$3)/SUMIF(OA_SQL_1!$A$1:$A$3,"DL",OA_SQL_1!$I$1:$I$3)))*100 -> 64804.124 | G8: =((UA_SQL_1!$P$2/UA_SQL_1!$M$2)-(SUMIF(OA_SQL_1!$A$1:$A$3,"AA",OA_SQL_1!$J$1:$J$3)/SUMIF(OA_SQL_1!$A$1:$A$3,"AA",OA_SQL_1!$I$1:$I$3)))*100 -> 64811.156 | H8: =RANK!F4 -> 1
B9: D:00 | C9: =UA_SQL_1!O2/UA_SQL_1!M2 -> 5.5 | D9: =UA_SQL_1!G2/UA_SQL_1!E2 -> 0.6943662 | E9: =SUMIF(EX_Goals!$B:$B,'PAGE_1 (4)'!#REF!,EX_Goals!$C:$C) -> 0
B10: STAR D:00 | C10: =UA_SQL_1!S2/UA_SQL_1!R2 -> 1.1911403 | D10: =UA_SQL_1!K2/UA_SQL_1!J2 -> 0.19176262 | E10: =SUMIF(EX_Goals!$B:$B,'PAGE_1 (4)'!#REF!,EX_Goals!$F:$F) -> 0
B11: Controllable Completion | C11: =(UA_SQL_1!M2-UA_SQL_1!T2)/UA_SQL_1!M2 -> -135.5 | D11: =(UA_SQL_1!E2-UA_SQL_1!L2)/UA_SQL_1!E2 -> 0.87552817 | E11: =SUMIF(EX_Goals!$B:$B,'PAGE_1 (4)'!#REF!,EX_Goals!$G:$G) -> 0
B12: Total diverts | C12: =SUMIFS(TOTAL_DIVERTS_SQL_5!$B:$B,TOTAL_DIVERTS_SQL_5!A:A,"YEST") -> 3 | D12: =SUMIFS(TOTAL_DIVERTS_SQL_5!$B:$B,TOTAL_DIVERTS_SQL_5!A:A,"MTD") -> 9
B13: Diverts recovered | C13: =SUMIF(DIVERTS_RECOVERED_SQL_6!$A:$A,"YEST",DIVERTS_RECOVERED_SQL_6!$C:$C) -> 1 | D13: =SUMIF(DIVERTS_RECOVERED_SQL_6!$A:$A,"MTD",DIVERTS_RECOVERED_SQL_6!$C:$C) -> 6
B16: Reliability Snapshot - Hubs
B17: Market | C17: D:00 | D17: CS D:00 | E17: DL Diff. | F17: AA Diff. | G17: Rank | H17: Completion | I17: DL Diff. | J17: AA Diff. | K17: Rank
B18: Denver | C18: =SUMIFS(UA_HUB_SQL_7!J:J,UA_HUB_SQL_7!$B:$B,'PAGE_1 (4)'!B18)/SUMIFS(UA_HUB_SQL_7!$F:$F,UA_HUB_SQL_7!$B:$B,'PAGE_1 (4)'!B18) -> 0.88 | D18: =SUMIFS(UA_HUB_SQL_7!K:K,UA_HUB_SQL_7!B:B,'PAGE_1 (4)'!B18)/SUMIFS(UA_HUB_SQL_7!F:F,UA_HUB_SQL_7!B:B,'PAGE_1 (4)'!B18) -> 0.89142857 | E18: - | G18: - | H18: =SUMIFS(UA_HUB_SQL_7!G:G,UA_HUB_SQL_7!$B:$B,'PAGE_1 (4)'!B18)/SUMIFS(UA_HUB_SQL_7!$F:$F,UA_HUB_SQL_7!$B:$B,'PAGE_1 (4)'!B18) -> 0.0057142857 | I18: - | J18: - | K18: -
B19: New York | C19: =SUMIFS(UA_HUB_SQL_7!J:J,UA_HUB_SQL_7!$B:$B,'PAGE_1 (4)'!B19)/SUMIFS(UA_HUB_SQL_7!$F:$F,UA_HUB_SQL_7!$B:$B,'PAGE_1 (4)'!B19) -> 0.78070175 | D19: =SUMIFS(UA_HUB_SQL_7!K:K,UA_HUB_SQL_7!B:B,'PAGE_1 (4)'!B19)/SUMIFS(UA_HUB_SQL_7!F:F,UA_HUB_SQL_7!B:B,'PAGE_1 (4)'!B19) -> 0.81578947 | E19: DL - 0.7 AA - (8.0) | G19: =RANK!F9 -> 1 | H19: =SUMIFS(UA_HUB_SQL_7!G:G,UA_HUB_SQL_7!$B:$B,'PAGE_1 (4)'!B19)/SUMIFS(UA_HUB_SQL_7!$F:$F,UA_HUB_SQL_7!$B:$B,'PAGE_1 (4)'!B19) -> 0 | I19: =IFERROR(((SUMIFS(UA_HUB_SQL_7!$G:$G,UA_HUB_SQL_7!$B:$B,'PAGE_1 (4)'!B19)/SUMIFS(UA_HUB_SQL_7!$F:$F,UA_HUB_SQL_7!$B:$B,'PAGE_1 (4)'!B19))-(SUMIFS(OA_SQL_2!$L:$L,OA_SQL_2!$A:$A,'PAGE_1 (4)'!B19,OA_SQL_2!$B:$B,"DL")/SUMIFS(OA_SQL_2!$J:$J,OA_SQL_2!$A:$A,'PAGE_1 (4)'!B19,OA_SQL_2!$B:$B,"DL")))*100,"-") -> -100 | J19: =IFERROR(((SUMIFS(UA_HUB_SQL_7!$G:$G,UA_HUB_SQL_7!$B:$B,'PAGE_1 (4)'!B19)/SUMIFS(UA_HUB_SQL_7!$F:$F,UA_HUB_SQL_7!$B:$B,'PAGE_1 (4)'!B19))-(SUMIFS(OA_SQL_2!$L:$L,OA_SQL_2!$A:$A,'PAGE_1 (4)'!B19,OA_SQL_2!$B:$B,"AA")/SUMIFS(OA_SQL_2!$J:$J,OA_SQL_2!$A:$A,'PAGE_1 (4)'!B19,OA_SQL_2!$B:$B,"AA")))*100,"-") -> -100 | K19: =RANK!F20 -> 1
B20: Washington DC | C20: =SUMIFS(UA_HUB_SQL_7!J:J,UA_HUB_SQL_7!$B:$B,'PAGE_1 (4)'!B20)/SUMIFS(UA_HUB_SQL_7!$F:$F,UA_HUB_SQL_7!$B:$B,'PAGE_1 (4)'!B20) -> 0.73228346 | D20: =SUMIFS(UA_HUB_SQL_7!K:K,UA_HUB_SQL_7!B:B,'PAGE_1 (4)'!B20)/SUMIFS(UA_HUB_SQL_7!F:F,UA_HUB_SQL_7!B:B,'PAGE_1 (4)'!B20) -> 0.77952756 | E20: DL - 0.7 AA - (8.0) | G20: =RANK!F10 -> 1 | H20: =SUMIFS(UA_HUB_SQL_7!G:G,UA_HUB_SQL_7!$B:$B,'PAGE_1 (4)'!B20)/SUMIFS(UA_HUB_SQL_7!$F:$F,UA_HUB_SQL_7!$B:$B,'PAGE_1 (4)'!B20) -> 0 | I20: =IFERROR(((SUMIFS(UA_HUB_SQL_7!$G:$G,UA_HUB_SQL_7!$B:$B,'PAGE_1 (4)'!B20)/SUMIFS(UA_HUB_SQL_7!$F:$F,UA_HUB_SQL_7!$B:$B,'PAGE_1 (4)'!B20))-(SUMIFS(OA_SQL_2!$L:$L,OA_SQL_2!$A:$A,'PAGE_1 (4)'!B20,OA_SQL_2!$B:$B,"DL")/SUMIFS(OA_SQL_2!$J:$J,OA_SQL_2!$A:$A,'PAGE_1 (4)'!B20,OA_SQL_2!$B:$B,"DL")))*100,"-") -> -100 | J20: =IFERROR(((SUMIFS(UA_HUB_SQL_7!$G:$G,UA_HUB_SQL_7!$B:$B,'PAGE_1 (4)'!B20)/SUMIFS(UA_HUB_SQL_7!$F:$F,UA_HUB_SQL_7!$B:$B,'PAGE_1 (4)'!B20))-(SUMIFS(OA_SQL_2!$L:$L,OA_SQL_2!$A:$A,'PAGE_1 (4)'!B20,OA_SQL_2!$B:$B,"AA")/SUMIFS(OA_SQL_2!$J:$J,OA_SQL_2!$A:$A,'PAGE_1 (4)'!B20,OA_SQL_2!$B:$B,"AA")))*100,"-") -> -100 | K20: =RANK!F21 -> 1
B21: Texas | C21: =SUMIFS(UA_HUB_SQL_7!J:J,UA_HUB_SQL_7!$B:$B,'PAGE_1 (4)'!B21)/SUMIFS(UA_HUB_SQL_7!$F:$F,UA_HUB_SQL_7!$B:$B,'PAGE_1 (4)'!B21) -> 0.74251497 | D21: =SUMIFS(UA_HUB_SQL_7!K:K,UA_HUB_SQL_7!B:B,'PAGE_1 (4)'!B21)/SUMIFS(UA_HUB_SQL_7!F:F,UA_HUB_SQL_7!B:B,'PAGE_1 (4)'!B21) -> 0.76047904 | E21: AA - (8.0) | G21: =RANK!F11 -> 2 | H21: =SUMIFS(UA_HUB_SQL_7!G:G,UA_HUB_SQL_7!$B:$B,'PAGE_1 (4)'!B21)/SUMIFS(UA_HUB_SQL_7!$F:$F,UA_HUB_SQL_7!$B:$B,'PAGE_1 (4)'!B21) -> 0 | I21: - | J21: =IFERROR(((SUMIFS(UA_HUB_SQL_7!$G:$G,UA_HUB_SQL_7!$B:$B,'PAGE_1 (4)'!B21)/SUMIFS(UA_HUB_SQL_7!$F:$F,UA_HUB_SQL_7!$B:$B,'PAGE_1 (4)'!B21))-(SUMIFS(OA_SQL_2!$L:$L,OA_SQL_2!$A:$A,'PAGE_1 (4)'!B21,OA_SQL_2!$B:$B,"AA")/SUMIFS(OA_SQL_2!$J:$J,OA_SQL_2!$A:$A,'PAGE_1 (4)'!B21,OA_SQL_2!$B:$B,"AA")))*100,"-") -> -100 | K21: =RANK!F22 -> 1
B22: Los Angeles | C22: =SUMIFS(UA_HUB_SQL_7!J:J,UA_HUB_SQL_7!$B:$B,'PAGE_1 (4)'!B22)/SUMIFS(UA_HUB_SQL_7!$F:$F,UA_HUB_SQL_7!$B:$B,'PAGE_1 (4)'!B22) -> 0.55172414 | D22: =SUMIFS(UA_HUB_SQL_7!K:K,UA_HUB_SQL_7!B:B,'PAGE_1 (4)'!B22)/SUMIFS(UA_HUB_SQL_7!F:F,UA_HUB_SQL_7!B:B,'PAGE_1 (4)'!B22) -> 0.5862069 | E22: DL - 0.7 AA - (8.0) | G22: =RANK!F12 -> 3 | H22: =SUMIFS(UA_HUB_SQL_7!G:G,UA_HUB_SQL_7!$B:$B,'PAGE_1 (4)'!B22)/SUMIFS(UA_HUB_SQL_7!$F:$F,UA_HUB_SQL_7!$B:$B,'PAGE_1 (4)'!B22) -> 0.034482759 | I22: =IFERROR(((SUMIFS(UA_HUB_SQL_7!$G:$G,UA_HUB_SQL_7!$B:$B,'PAGE_1 (4)'!B22)/SUMIFS(UA_HUB_SQL_7!$F:$F,UA_HUB_SQL_7!$B:$B,'PAGE_1 (4)'!B22))-(SUMIFS(OA_SQL_2!$L:$L,OA_SQL_2!$A:$A,'PAGE_1 (4)'!B22,OA_SQL_2!$B:$B,"DL")/SUMIFS(OA_SQL_2!$J:$J,OA_SQL_2!$A:$A,'PAGE_1 (4)'!B22,OA_SQL_2!$B:$B,"DL")))*100,"-") -> -93.521421 | J22: =IFERROR(((SUMIFS(UA_HUB_SQL_7!$G:$G,UA_HUB_SQL_7!$B:$B,'PAGE_1 (4)'!B22)/SUMIFS(UA_HUB_SQL_7!$F:$F,UA_HUB_SQL_7!$B:$B,'PAGE_1 (4)'!B22))-(SUMIFS(OA_SQL_2!$L:$L,OA_SQL_2!$A:$A,'PAGE_1 (4)'!B22,OA_SQL_2!$B:$B,"AA")/SUMIFS(OA_SQL_2!$J:$J,OA_SQL_2!$A:$A,'PAGE_1 (4)'!B22,OA_SQL_2!$B:$B,"AA")))*100,"-") -> -96.551724 | K22: =RANK!F23 -> 3
B23: Chicago | C23: =SUMIFS(UA_HUB_SQL_7!J:J,UA_HUB_SQL_7!$B:$B,'PAGE_1 (4)'!B23)/SUMIFS(UA_HUB_SQL_7!$F:$F,UA_HUB_SQL_7!$B:$B,'PAGE_1 (4)'!B23) -> 0.59615385 | D23: =SUMIFS(UA_HUB_SQL_7!K:K,UA_HUB_SQL_7!B:B,'PAGE_1 (4)'!B23)/SUMIFS(UA_HUB_SQL_7!F:F,UA_HUB_SQL_7!B:B,'PAGE_1 (4)'!B23) -> 0.67307692 | E23: AA - (8.0) | G23: =RANK!F13 -> 2 | H23: =SUMIFS(UA_HUB_SQL_7!G:G,UA_HUB_SQL_7!$B:$B,'PAGE_1 (4)'!B23)/SUMIFS(UA_HUB_SQL_7!$F:$F,UA_HUB_SQL_7!$B:$B,'PAGE_1 (4)'!B23) -> 0 | I23: - | J23: =IFERROR(((SUMIFS(UA_HUB_SQL_7!$G:$G,UA_HUB_SQL_7!$B:$B,'PAGE_1 (4)'!B23)/SUMIFS(UA_HUB_SQL_7!$F:$F,UA_HUB_SQL_7!$B:$B,'PAGE_1 (4)'!B23))-(SUMIFS(OA_SQL_2!$L:$L,OA_SQL_2!$A:$A,'PAGE_1 (4)'!B23,OA_SQL_2!$B:$B,"AA")/SUMIFS(OA_SQL_2!$J:$J,OA_SQL_2!$A:$A,'PAGE_1 (4)'!B23,OA_SQL_2!$B:$B,"AA")))*100,"-") -> -100 | K23: =RANK!F24 -> 1
B24: San Francisco | C24: =SUMIFS(UA_HUB_SQL_7!J:J,UA_HUB_SQL_7!$B:$B,'PAGE_1 (4)'!B24)/SUMIFS(UA_HUB_SQL_7!$F:$F,UA_HUB_SQL_7!$B:$B,'PAGE_1 (4)'!B24) -> 0.61016949 | D24: =SUMIFS(UA_HUB_SQL_7!K:K,UA_HUB_SQL_7!B:B,'PAGE_1 (4)'!B24)/SUMIFS(UA_HUB_SQL_7!F:F,UA_HUB_SQL_7!B:B,'PAGE_1 (4)'!B24) -> 0.6440678 | E24: AS - (8.0) | G24: - | H24: =SUMIFS(UA_HUB_SQL_7!G:G,UA_HUB_SQL_7!$B:$B,'PAGE_1 (4)'!B24)/SUMIFS(UA_HUB_SQL_7!$F:$F,UA_HUB_SQL_7!$B:$B,'PAGE_1 (4)'!B24) -> 0.084745763 | I24: - | J24: - | K24: -
B27: Cancel Detail
B28: Express Partner | C28: Scheduled Departures | D28: Weather & ATC | E28: Technical Operations | F28: Flight Operations | G28: Inflight Services | H28: Airport Operations | I28: Network Operations | J28: IT | K28: Catering Operations | L28: Other | M28: Total Cancels | N28: ES covered for this partner | O28: Net Cancel | P28: ES covered by this partner
B29: EV - ExpressJet | C29: =SUMIF(SCH_DEP_SQL_4!$A:$A,'PAGE_1 (4)'!R29,SCH_DEP_SQL_4!$E:$E) -> 0 | D29: =IF(SUMIFS(CNXL_SQL_2!$F:$F,CNXL_SQL_2!$A:$A,'PAGE_1 (4)'!$R29,CNXL_SQL_2!$D:$D,'PAGE_1 (4)'!$S$29)=0,"",SUMIFS(CNXL_SQL_2!$F:$F,CNXL_SQL_2!$A:$A,'PAGE_1 (4)'!$R29,CNXL_SQL_2!$D:$D,'PAGE_1 (4)'!$S$29)) | E29: =IF(SUMIFS(CNXL_SQL_2!$F:$F,CNXL_SQL_2!$A:$A,'PAGE_1 (4)'!$R29,CNXL_SQL_2!$D:$D,'PAGE_1 (4)'!$S$30)=0,"",SUMIFS(CNXL_SQL_2!$F:$F,CNXL_SQL_2!$A:$A,'PAGE_1 (4)'!$R29,CNXL_SQL_2!$D:$D,'PAGE_1 (4)'!$S$30)) | F29: =IF(SUMIFS(CNXL_SQL_2!$F:$F,CNXL_SQL_2!$A:$A,'PAGE_1 (4)'!$R29,CNXL_SQL_2!$D:$D,'PAGE_1 (4)'!$S$31)=0,"",SUMIFS(CNXL_SQL_2!$F:$F,CNXL_SQL_2!$A:$A,'PAGE_1 (4)'!$R29,CNXL_SQL_2!$D:$D,'PAGE_1 (4)'!$S$31)) | G29: =IF(SUMIFS(CNXL_SQL_2!$F:$F,CNXL_SQL_2!$A:$A,'PAGE_1 (4)'!$R29,CNXL_SQL_2!$D:$D,'PAGE_1 (4)'!$S$32)=0,"",SUMIFS(CNXL_SQL_2!$F:$F,CNXL_SQL_2!$A:$A,'PAGE_1 (4)'!$R29,CNXL_SQL_2!$D:$D,'PAGE_1 (4)'!$S$32)) | H29: =IF(SUMIFS(CNXL_SQL_2!$F:$F,CNXL_SQL_2!$A:$A,'PAGE_1 (4)'!$R29,CNXL_SQL_2!$D:$D,'PAGE_1 (4)'!$S$33)=0,"",SUMIFS(CNXL_SQL_2!$F:$F,CNXL_SQL_2!$A:$A,'PAGE_1 (4)'!$R29,CNXL_SQL_2!$D:$D,'PAGE_1 (4)'!$S$33)) | I29: =IF(SUMIFS(CNXL_SQL_2!$F:$F,CNXL_SQL_2!$A:$A,'PAGE_1 (4)'!$R29,CNXL_SQL_2!$D:$D,'PAGE_1 (4)'!$S$34)=0,"",SUMIFS(CNXL_SQL_2!$F:$F,CNXL_SQL_2!$A:$A,'PAGE_1 (4)'!$R29,CNXL_SQL_2!$D:$D,'PAGE_1 (4)'!$S$34)) | J29: =IF(SUMIFS(CNXL_SQL_2!$F:$F,CNXL_SQL_2!$A:$A,'PAGE_1 (4)'!$R29,CNXL_SQL_2!$D:$D,'PAGE_1 (4)'!$S$35)=0,"",SUMIFS(CNXL_SQL_2!$F:$F,CNXL_SQL_2!$A:$A,'PAGE_1 (4)'!$R29,CNXL_SQL_2!$D:$D,'PAGE_1 (4)'!$S$35)) | K29: =IF(SUMIFS(CNXL_SQL_2!$F:$F,CNXL_SQL_2!$A:$A,'PAGE_1 (4)'!$R29,CNXL_SQL_2!$D:$D,'PAGE_1 (4)'!$S$36)=0,"",SUMIFS(CNXL_SQL_2!$F:$F,CNXL_SQL_2!$A:$A,'PAGE_1 (4)'!$R29,CNXL_SQL_2!$D:$D,'PAGE_1 (4)'!$S$36)) | L29: =IF(SUMIFS(CNXL_SQL_2!$F:$F,CNXL_SQL_2!$A:$A,'PAGE_1 (4)'!$R29,CNXL_SQL_2!$D:$D,'PAGE_1 (4)'!$S$37)=0,"",SUMIFS(CNXL_SQL_2!$F:$F,CNXL_SQL_2!$A:$A,'PAGE_1 (4)'!$R29,CNXL_SQL_2!$D:$D,'PAGE_1 (4)'!$S$37)) | M29: =IF(SUM(D29:L29)=0,"",SUM(D29:L29)) | N29: =ES_MATRIX!K3 | O29: =IFERROR(M29-ES_MATRIX!L3,"") | P29: =IF(SUMIF(CNXL_SQL_2!$E:$E,'PAGE_1 (4)'!R29,CNXL_SQL_2!$F:$F)=0,"",SUMIF(CNXL_SQL_2!$E:$E,'PAGE_1 (4)'!R29,CNXL_SQL_2!$F:$F)) | R29: EV | S29: WEATHER/ATC
B30: OO - SkyWest | C30: =SUMIF(SCH_DEP_SQL_4!$A:$A,'PAGE_1 (4)'!R30,SCH_DEP_SQL_4!$E:$E) -> 816 | D30: =IF(SUMIFS(CNXL_SQL_2!$F:$F,CNXL_SQL_2!$A:$A,'PAGE_1 (4)'!$R30,CNXL_SQL_2!$D:$D,'PAGE_1 (4)'!$S$29)=0,"",SUMIFS(CNXL_SQL_2!$F:$F,CNXL_SQL_2!$A:$A,'PAGE_1 (4)'!$R30,CNXL_SQL_2!$D:$D,'PAGE_1 (4)'!$S$29)) -> 10 | E30: =IF(SUMIFS(CNXL_SQL_2!$F:$F,CNXL_SQL_2!$A:$A,'PAGE_1 (4)'!$R30,CNXL_SQL_2!$D:$D,'PAGE_1 (4)'!$S$30)=0,"",SUMIFS(CNXL_SQL_2!$F:$F,CNXL_SQL_2!$A:$A,'PAGE_1 (4)'!$R30,CNXL_SQL_2!$D:$D,'PAGE_1 (4)'!$S$30)) | F30: =IF(SUMIFS(CNXL_SQL_2!$F:$F,CNXL_SQL_2!$A:$A,'PAGE_1 (4)'!$R30,CNXL_SQL_2!$D:$D,'PAGE_1 (4)'!$S$31)=0,"",SUMIFS(CNXL_SQL_2!$F:$F,CNXL_SQL_2!$A:$A,'PAGE_1 (4)'!$R30,CNXL_SQL_2!$D:$D,'PAGE_1 (4)'!$S$31)) | G30: =IF(SUMIFS(CNXL_SQL_2!$F:$F,CNXL_SQL_2!$A:$A,'PAGE_1 (4)'!$R30,CNXL_SQL_2!$D:$D,'PAGE_1 (4)'!$S$32)=0,"",SUMIFS(CNXL_SQL_2!$F:$F,CNXL_SQL_2!$A:$A,'PAGE_1 (4)'!$R30,CNXL_SQL_2!$D:$D,'PAGE_1 (4)'!$S$32)) | H30: =IF(SUMIFS(CNXL_SQL_2!$F:$F,CNXL_SQL_2!$A:$A,'PAGE_1 (4)'!$R30,CNXL_SQL_2!$D:$D,'PAGE_1 (4)'!$S$33)=0,"",SUMIFS(CNXL_SQL_2!$F:$F,CNXL_SQL_2!$A:$A,'PAGE_1 (4)'!$R30,CNXL_SQL_2!$D:$D,'PAGE_1 (4)'!$S$33)) | I30: =IF(SUMIFS(CNXL_SQL_2!$F:$F,CNXL_SQL_2!$A:$A,'PAGE_1 (4)'!$R30,CNXL_SQL_2!$D:$D,'PAGE_1 (4)'!$S$34)=0,"",SUMIFS(CNXL_SQL_2!$F:$F,CNXL_SQL_2!$A:$A,'PAGE_1 (4)'!$R30,CNXL_SQL_2!$D:$D,'PAGE_1 (4)'!$S$34)) | J30: =IF(SUMIFS(CNXL_SQL_2!$F:$F,CNXL_SQL_2!$A:$A,'PAGE_1 (4)'!$R30,CNXL_SQL_2!$D:$D,'PAGE_1 (4)'!$S$35)=0,"",SUMIFS(CNXL_SQL_2!$F:$F,CNXL_SQL_2!$A:$A,'PAGE_1 (4)'!$R30,CNXL_SQL_2!$D:$D,'PAGE_1 (4)'!$S$35)) | K30: =IF(SUMIFS(CNXL_SQL_2!$F:$F,CNXL_SQL_2!$A:$A,'PAGE_1 (4)'!$R30,CNXL_SQL_2!$D:$D,'PAGE_1 (4)'!$S$36)=0,"",SUMIFS(CNXL_SQL_2!$F:$F,CNXL_SQL_2!$A:$A,'PAGE_1 (4)'!$R30,CNXL_SQL_2!$D:$D,'PAGE_1 (4)'!$S$36)) | L30: =IF(SUMIFS(CNXL_SQL_2!$F:$F,CNXL_SQL_2!$A:$A,'PAGE_1 (4)'!$R30,CNXL_SQL_2!$D:$D,'PAGE_1 (4)'!$S$37)=0,"",SUMIFS(CNXL_SQL_2!$F:$F,CNXL_SQL_2!$A:$A,'PAGE_1 (4)'!$R30,CNXL_SQL_2!$D:$D,'PAGE_1 (4)'!$S$37)) | M30: =IF(SUM(D30:L30)=0,"",SUM(D30:L30)) -> 10 | N30: =ES_MATRIX!K4 | O30: =IFERROR(M30-ES_MATRIX!L4,"") -> 10 | P30: =IF(SUMIF(CNXL_SQL_2!$E:$E,'PAGE_1 (4)'!R30,CNXL_SQL_2!$F:$F)=0,"",SUMIF(CNXL_SQL_2!$E:$E,'PAGE_1 (4)'!R30,CNXL_SQL_2!$F:$F)) | R30: OO | S30: TECHNICAL OPERATIONS-AIRCRAFT
